Workbook

Sheet Analysis
A1: Technical Errors Breakdown | G1: Errors by Game | M1: Voided Games Breakdown | AF1: TOTAL DAILY ERRORS BREAKDOWN | BL1: Total Errors/Table MTD | BN1: Ave. Daily Errors | BT1: =$AF$2 -> 01.01.2025 | BU1: =$AG$2 -> 02.01.2025 | BV1: =$AH$2 -> 03.01.2025 | BW1: =$AI$2 -> 04.01.2025 | BX1: =$AJ$2 -> 05.01.2025 | BY1: =$AK$2 -> 06.01.2025 | BZ1: =$AL$2 -> 07.9.2025 | CA1: =$AM$2 -> 08.01.2025 | CB1: =$AN$2 -> 09.01.2025 | CC1: =$AO$2 -> 10.01.2025 | CD1: =$AP$2 -> 11.01.2025 | CE1: =$AQ$2 -> 12.01.2025 | CF1: =$AR$2 -> 13.01.2025 | CG1: =$AS$2 -> 14.01.2025 | CH1: =$AT$2 -> 15.01.2025 | CI1: =$AU$2 -> 16.01.2025 | CJ1: =$AV$2 -> 17.01.2025 | CK1: =$AW$2 -> 18.01.2025 | CL1: =$AX$2 -> 19.01.2025 | CM1: =$AY$2 -> 20.01.2025 | CN1: =$AZ$2 -> 21.01.2025 | CO1: =$BA$2 -> 22.01.2025 | CP1: =$BB$2 -> 23.01.2025 | CQ1: =$BC$2 -> 24.01.2025 | CR1: =$BD$2 -> 25.01.2025 | CS1: =$BE$2 -> 26.01.2025 | CT1: =$BF$2 -> 27.01.2025 | CU1: =$BG$2 -> 28.01.2025 | CV1: =$BH$2 -> 29.01.2025 | CW1: =$BI$2 -> 30.01.2025 | CX1: =$BJ$2 -> 31.01.2025 | CZ1: Total Voids/Table/MTD | DB1: Ave. Voids/Table/Day
A2: Technical Error Type. | B2: Total Number of Errors | C2: Bacc Tech Errors | D2: Roulette Tech Errors | E2: Sic Bo Tech Errors | G2: Table No. | H2: Total No. of Errors | I2: No. of Tech. Errors | J2: No. of Hum. Errors | K2: Game Ended with wrong Result | M2: Table No. | N2: Total No. of Voids | O2: No. of Tech. Voids | P2: No. of Hum. Error Voids | Q2: System Voids | R2: Manual Voids | AE2: Table Code | AF2: 01.01.2025 | AG2: 02.01.2025 | AH2: 03.01.2025 | AI2: 04.01.2025 | AJ2: 05.01.2025 | AK2: 06.01.2025 | AL2: 07.9.2025 | AM2: 08.01.2025 | AN2: 09.01.2025 | AO2: 10.01.2025 | AP2: 11.01.2025 | AQ2: 12.01.2025 | AR2: 13.01.2025 | AS2: 14.01.2025 | AT2: 15.01.2025 | AU2: 16.01.2025 | AV2: 17.01.2025 | AW2: 18.01.2025 | AX2: 19.01.2025 | AY2: 20.01.2025 | AZ2: 21.01.2025 | BA2: 22.01.2025 | BB2: 23.01.2025 | BC2: 24.01.2025 | BD2: 25.01.2025 | BE2: 26.01.2025 | BF2: 27.01.2025 | BG2: 28.01.2025 | BH2: 29.01.2025 | BI2: 30.01.2025 | BJ2: 31.01.2025 | BO2: Table Code | BS2: Table Code | BT2: DAILY SYSTEM VOIDS | DC2: Table Code
A3: TV-B | B3: =COUNTIF(Errors!$I$3:$I$3008,$A3) -> 45 | C3: =COUNTIFS(Errors!$I$3:$I$3008,$A3,Errors!$J$3:$J$3008,"Bacc") -> 43 | D3: =COUNTIFS(Errors!$I$3:$I$3008,$A3,Errors!$J$3:$J$3008,"Rou") -> 2 | E3: =COUNTIFS(Errors!$I$3:$I$3008,$A3,Errors!$J$3:$J$3008,"Sic Bo") -> 0 | H3: =COUNTIF(Errors!$F$3:$F$3008,$G3) -> 0 | I3: =COUNTIFS(Errors!$F$3:$F$3008,$G3,Errors!$I$3:$I$3008,"TV*") -> 0 | J3: =COUNTIFS(Errors!$F$3:$F$3008,$G3,Errors!$I$3:$I$3008,"<>TV*") -> 0 | K3: =COUNTIFS(Errors!$F$3:$F$3008,$G3,Errors!$Q$3:$Q$3008,"yes") -> 0 | N3: =COUNTIFS(Errors!$O$3:$O$3008,"Yes",Errors!$F$3:$F$3008,$M3)+COUNTIFS(Errors!$P$3:$P$3008,"Yes",Errors!$F$3:$F$3008,$M3) -> 0 | O3: =COUNTIFS(Errors!$O$3:$O$3008,"Yes",Errors!$F$3:$F$3008,$M3,Errors!$I$3:$I$3008,"TV*")+COUNTIFS(Errors!$P$3:$P$3008,"Yes",Errors!$F$3:$F$3008,$M3,Errors!$I$3:$I$3008,"TV*") -> 0 | P3: =COUNTIFS(Errors!$O$3:$O$3008,"Yes",Errors!$F$3:$F$3008,$M3,Errors!$I$3:$I$3008,"<>TV*")+COUNTIFS(Errors!$P$3:$P$3008,"Yes",Errors!$F$3:$F$3008,$M3,Errors!$I$3:$I$3008,"<>TV*") -> 0 | Q3: =COUNTIFS(Errors!$F$3:$F$3008,$M3,Errors!$O$3:$O$3008,"yes") -> 0 | R3: =COUNTIFS(Errors!$F$3:$F$3008,$M3,Errors!$P$3:$P$3008,"yes") -> 0 | AF3: =COUNTIFS(Errors!$F:$F,Analysis!$AE32,Errors!$D:$D,Analysis!$AF$2) -> 0 | AG3: =COUNTIFS(Errors!$F:$F,Analysis!$AE32,Errors!$D:$D,Analysis!$AG$2) -> 0 | AH3: =COUNTIFS(Errors!$F:$F,Analysis!$AE32,Errors!$D:$D,Analysis!$AH$2) -> 0 | AI3: =COUNTIFS(Errors!$F:$F,Analysis!$AE32,Errors!$D:$D,Analysis!$AI$2) -> 0 | AJ3: =COUNTIFS(Errors!$F:$F,Analysis!$AE32,Errors!$D:$D,Analysis!$AJ$2) -> 0 | AK3: =COUNTIFS(Errors!$F:$F,Analysis!$AE32,Errors!$D:$D,Analysis!$AK$2) -> 0 | AL3: =COUNTIFS(Errors!$F:$F,Analysis!$AE32,Errors!$D:$D,Analysis!$AL$2) -> 0 | AM3: =COUNTIFS(Errors!$F:$F,Analysis!$AE32,Errors!$D:$D,Analysis!$AM$2) -> 0 | AN3: =COUNTIFS(Errors!$F:$F,Analysis!$AE32,Errors!$D:$D,Analysis!$AN$2) -> 0 | AO3: =COUNTIFS(Errors!$F:$F,Analysis!$AE32,Errors!$D:$D,Analysis!$AO$2) -> 0 | AP3: =COUNTIFS(Errors!$F:$F,Analysis!$AE32,Errors!$D:$D,Analysis!$AP$2) -> 0 | AQ3: =COUNTIFS(Errors!$F:$F,Analysis!$AE32,Errors!$D:$D,Analysis!$AQ$2) -> 0 | AR3: =COUNTIFS(Errors!$F:$F,Analysis!$AE32,Errors!$D:$D,Analysis!$AR$2) -> 0 | AS3: =COUNTIFS(Errors!$F:$F,Analysis!$AE32,Errors!$D:$D,Analysis!$AS$2) -> 0 | AT3: =COUNTIFS(Errors!$F:$F,Analysis!$AE32,Errors!$D:$D,Analysis!$AT$2) -> 0 | AU3: =COUNTIFS(Errors!$F:$F,Analysis!$AE32,Errors!$D:$D,Analysis!$AU$2) -> 0 | AV3: =COUNTIFS(Errors!$F:$F,Analysis!$AE32,Errors!$D:$D,Analysis!$AV$2) -> 0 | AW3: =COUNTIFS(Errors!$F:$F,Analysis!$AE32,Errors!$D:$D,Analysis!$AW$2) -> 0 | AX3: =COUNTIFS(Errors!$F:$F,Analysis!$AE32,Errors!$D:$D,Analysis!$AX$2) -> 0 | AY3: =COUNTIFS(Errors!$F:$F,Analysis!$AE32,Errors!$D:$D,Analysis!$AY$2) -> 0 | AZ3: =COUNTIFS(Errors!$F:$F,Analysis!$AE32,Errors!$D:$D,Analysis!$AZ$2) -> 0 | BA3: =COUNTIFS(Errors!$F:$F,Analysis!$AE32,Errors!$D:$D,Analysis!$BA$2) -> 0 | BB3: =COUNTIFS(Errors!$F:$F,Analysis!$AE32,Errors!$D:$D,Analysis!$BB$2) -> 0 | BC3: =COUNTIFS(Errors!$F:$F,Analysis!$AE32,Errors!$D:$D,Analysis!$BC$2) -> 0 | BD3: =COUNTIFS(Errors!$F:$F,Analysis!$AE32,Errors!$D:$D,Analysis!$BD$2) -> 0 | BE3: =COUNTIFS(Errors!$F:$F,Analysis!$AE32,Errors!$D:$D,Analysis!$BE$2) -> 0 | BF3: =COUNTIFS(Errors!$F:$F,Analysis!$AE32,Errors!$D:$D,Analysis!$BF$2) -> 0 | BG3: =COUNTIFS(Errors!$F:$F,Analysis!$AE32,Errors!$D:$D,Analysis!$BG$2) -> 0 | BH3: =COUNTIFS(Errors!$F:$F,Analysis!$AE32,Errors!$D:$D,Analysis!$BH$2) -> 0 | BI3: =COUNTIFS(Errors!$F:$F,Analysis!$AE32,Errors!$D:$D,Analysis!$BI$2) -> 0 | BJ3: =COUNTIFS(Errors!$F:$F,Analysis!$AE32,Errors!$D:$D,Analysis!$BJ$2) -> 0 | BL3: =SUM(AF3:BJ3) -> 0 | BN3: =AVERAGE(AF3:BJ3) -> 0 | BO3: Baccarat_E1 | BS3: Baccarat_E1 | BT3: =COUNTIFS(Errors!$D:$D,Analysis!BT$1,Errors!$F:$F,Analysis!$BS3,Errors!$O:$O,"YES") -> 0 | BU3: =COUNTIFS(Errors!$D:$D,Analysis!BU$1,Errors!$F:$F,Analysis!$BS3,Errors!$O:$O,"YES") -> 0 | BV3: =COUNTIFS(Errors!$D:$D,Analysis!BV$1,Errors!$F:$F,Analysis!$BS3,Errors!$O:$O,"YES") -> 0 | BW3: =COUNTIFS(Errors!$D:$D,Analysis!BW$1,Errors!$F:$F,Analysis!$BS3,Errors!$O:$O,"YES") -> 0 | BX3: =COUNTIFS(Errors!$D:$D,Analysis!BX$1,Errors!$F:$F,Analysis!$BS3,Errors!$O:$O,"YES") -> 0 | BY3: =COUNTIFS(Errors!$D:$D,Analysis!BY$1,Errors!$F:$F,Analysis!$BS3,Errors!$O:$O,"YES") -> 0 | BZ3: =COUNTIFS(Errors!$D:$D,Analysis!BZ$1,Errors!$F:$F,Analysis!$BS3,Errors!$O:$O,"YES") -> 0 | CA3: =COUNTIFS(Errors!$D:$D,Analysis!CA$1,Errors!$F:$F,Analysis!$BS3,Errors!$O:$O,"YES") -> 0 | ... CX3: =COUNTIFS(Errors!$D:$D,Analysis!CX$1,Errors!$F:$F,Analysis!$BS3,Errors!$O:$O,"YES") -> 0 | CZ3: =SUM(BT3:CX3) -> 0 | DB3: =AVERAGE(BT3:CX3) -> 0 | DC3: Baccarat_E1
A4: TV-RO | B4: =COUNTIF(Errors!$I$3:$I$3008,$A4) -> 11 | C4: =COUNTIFS(Errors!$I$3:$I$3008,$A4,Errors!$J$3:$J$3008,"Bacc") -> 0 | D4: =COUNTIFS(Errors!$I$3:$I$3008,$A4,Errors!$J$3:$J$3008,"Rou") -> 11 | E4: =COUNTIFS(Errors!$I$3:$I$3008,$A4,Errors!$J$3:$J$3008,"Sic Bo") -> 0 | H4: =COUNTIF(Errors!$F$3:$F$3008,$G4) -> 0 | I4: =COUNTIFS(Errors!$F$3:$F$3008,$G4,Errors!$I$3:$I$3008,"TV*") -> 0 | J4: =COUNTIFS(Errors!$F$3:$F$3008,$G4,Errors!$I$3:$I$3008,"<>TV*") -> 0 | K4: =COUNTIFS(Errors!$F$3:$F$3008,$G4,Errors!$Q$3:$Q$3008,"yes") -> 0 | N4: =COUNTIFS(Errors!$O$3:$O$3008,"Yes",Errors!$F$3:$F$3008,$M4)+COUNTIFS(Errors!$P$3:$P$3008,"Yes",Errors!$F$3:$F$3008,$M4) -> 0 | O4: =COUNTIFS(Errors!$O$3:$O$3008,"Yes",Errors!$F$3:$F$3008,$M4,Errors!$I$3:$I$3008,"TV*")+COUNTIFS(Errors!$P$3:$P$3008,"Yes",Errors!$F$3:$F$3008,$M4,Errors!$I$3:$I$3008,"TV*") -> 0 | P4: =COUNTIFS(Errors!$O$3:$O$3008,"Yes",Errors!$F$3:$F$3008,$M4,Errors!$I$3:$I$3008,"<>TV*")+COUNTIFS(Errors!$P$3:$P$3008,"Yes",Errors!$F$3:$F$3008,$M4,Errors!$I$3:$I$3008,"<>TV*") -> 0 | Q4: =COUNTIFS(Errors!$F$3:$F$3008,$M4,Errors!$O$3:$O$3008,"yes") -> 0 | R4: =COUNTIFS(Errors!$F$3:$F$3008,$M4,Errors!$P$3:$P$3008,"yes") -> 0 | AF4: =COUNTIFS(Errors!$F:$F,Analysis!$AE33,Errors!$D:$D,Analysis!$AF$2) -> 0 | AG4: =COUNTIFS(Errors!$F:$F,Analysis!$AE33,Errors!$D:$D,Analysis!$AG$2) -> 0 | AH4: =COUNTIFS(Errors!$F:$F,Analysis!$AE33,Errors!$D:$D,Analysis!$AH$2) -> 0 | AI4: =COUNTIFS(Errors!$F:$F,Analysis!$AE33,Errors!$D:$D,Analysis!$AI$2) -> 0 | AJ4: =COUNTIFS(Errors!$F:$F,Analysis!$AE33,Errors!$D:$D,Analysis!$AJ$2) -> 0 | AK4: =COUNTIFS(Errors!$F:$F,Analysis!$AE33,Errors!$D:$D,Analysis!$AK$2) -> 0 | AL4: =COUNTIFS(Errors!$F:$F,Analysis!$AE33,Errors!$D:$D,Analysis!$AL$2) -> 0 | AM4: =COUNTIFS(Errors!$F:$F,Analysis!$AE33,Errors!$D:$D,Analysis!$AM$2) -> 0 | AN4: =COUNTIFS(Errors!$F:$F,Analysis!$AE33,Errors!$D:$D,Analysis!$AN$2) -> 0 | AO4: =COUNTIFS(Errors!$F:$F,Analysis!$AE33,Errors!$D:$D,Analysis!$AO$2) -> 0 | AP4: =COUNTIFS(Errors!$F:$F,Analysis!$AE33,Errors!$D:$D,Analysis!$AP$2) -> 0 | AQ4: =COUNTIFS(Errors!$F:$F,Analysis!$AE33,Errors!$D:$D,Analysis!$AQ$2) -> 0 | AR4: =COUNTIFS(Errors!$F:$F,Analysis!$AE33,Errors!$D:$D,Analysis!$AR$2) -> 0 | AS4: =COUNTIFS(Errors!$F:$F,Analysis!$AE33,Errors!$D:$D,Analysis!$AS$2) -> 0 | AT4: =COUNTIFS(Errors!$F:$F,Analysis!$AE33,Errors!$D:$D,Analysis!$AT$2) -> 0 | AU4: =COUNTIFS(Errors!$F:$F,Analysis!$AE33,Errors!$D:$D,Analysis!$AU$2) -> 0 | AV4: =COUNTIFS(Errors!$F:$F,Analysis!$AE33,Errors!$D:$D,Analysis!$AV$2) -> 0 | AW4: =COUNTIFS(Errors!$F:$F,Analysis!$AE33,Errors!$D:$D,Analysis!$AW$2) -> 0 | AX4: =COUNTIFS(Errors!$F:$F,Analysis!$AE33,Errors!$D:$D,Analysis!$AX$2) -> 0 | AY4: =COUNTIFS(Errors!$F:$F,Analysis!$AE33,Errors!$D:$D,Analysis!$AY$2) -> 0 | AZ4: =COUNTIFS(Errors!$F:$F,Analysis!$AE33,Errors!$D:$D,Analysis!$AZ$2) -> 0 | BA4: =COUNTIFS(Errors!$F:$F,Analysis!$AE33,Errors!$D:$D,Analysis!$BA$2) -> 0 | BB4: =COUNTIFS(Errors!$F:$F,Analysis!$AE33,Errors!$D:$D,Analysis!$BB$2) -> 0 | BC4: =COUNTIFS(Errors!$F:$F,Analysis!$AE33,Errors!$D:$D,Analysis!$BC$2) -> 0 | BD4: =COUNTIFS(Errors!$F:$F,Analysis!$AE33,Errors!$D:$D,Analysis!$BD$2) -> 0 | BE4: =COUNTIFS(Errors!$F:$F,Analysis!$AE33,Errors!$D:$D,Analysis!$BE$2) -> 0 | BF4: =COUNTIFS(Errors!$F:$F,Analysis!$AE33,Errors!$D:$D,Analysis!$BF$2) -> 0 | BG4: =COUNTIFS(Errors!$F:$F,Analysis!$AE33,Errors!$D:$D,Analysis!$BG$2) -> 0 | BH4: =COUNTIFS(Errors!$F:$F,Analysis!$AE33,Errors!$D:$D,Analysis!$BH$2) -> 0 | BI4: =COUNTIFS(Errors!$F:$F,Analysis!$AE33,Errors!$D:$D,Analysis!$BI$2) -> 0 | BJ4: =COUNTIFS(Errors!$F:$F,Analysis!$AE33,Errors!$D:$D,Analysis!$BJ$2) -> 0 | BL4: =SUM(AF4:BJ4) -> 0 | BN4: =AVERAGE(AF4:BJ4) -> 0 | BO4: Baccarat_E2 | BS4: Baccarat_E2 | BT4: =COUNTIFS(Errors!$D:$D,Analysis!BT$1,Errors!$F:$F,Analysis!$BS4,Errors!$O:$O,"YES") -> 0 | BU4: =COUNTIFS(Errors!$D:$D,Analysis!BU$1,Errors!$F:$F,Analysis!$BS4,Errors!$O:$O,"YES") -> 0 | BV4: =COUNTIFS(Errors!$D:$D,Analysis!BV$1,Errors!$F:$F,Analysis!$BS4,Errors!$O:$O,"YES") -> 0 | BW4: =COUNTIFS(Errors!$D:$D,Analysis!BW$1,Errors!$F:$F,Analysis!$BS4,Errors!$O:$O,"YES") -> 0 | BX4: =COUNTIFS(Errors!$D:$D,Analysis!BX$1,Errors!$F:$F,Analysis!$BS4,Errors!$O:$O,"YES") -> 0 | BY4: =COUNTIFS(Errors!$D:$D,Analysis!BY$1,Errors!$F:$F,Analysis!$BS4,Errors!$O:$O,"YES") -> 0 | BZ4: =COUNTIFS(Errors!$D:$D,Analysis!BZ$1,Errors!$F:$F,Analysis!$BS4,Errors!$O:$O,"YES") -> 0 | CA4: =COUNTIFS(Errors!$D:$D,Analysis!CA$1,Errors!$F:$F,Analysis!$BS4,Errors!$O:$O,"YES") -> 0 | ... CX4: =COUNTIFS(Errors!$D:$D,Analysis!CX$1,Errors!$F:$F,Analysis!$BS4,Errors!$O:$O,"YES") -> 0 | CZ4: =SUM(BT4:CX4) -> 0 | DB4: =AVERAGE(BT4:CX4) -> 0 | DC4: Baccarat_E2
A5: TV-1 | B5: =COUNTIF(Errors!$I$3:$I$3008,$A5) -> 0 | C5: =COUNTIFS(Errors!$I$3:$I$3008,$A5,Errors!$J$3:$J$3008,"Bacc") -> 0 | D5: =COUNTIFS(Errors!$I$3:$I$3008,$A5,Errors!$J$3:$J$3008,"Rou") -> 0 | E5: =COUNTIFS(Errors!$I$3:$I$3008,$A5,Errors!$J$3:$J$3008,"Sic Bo") -> 0 | H5: =COUNTIF(Errors!$F$3:$F$3008,$G5) -> 0 | I5: =COUNTIFS(Errors!$F$3:$F$3008,$G5,Errors!$I$3:$I$3008,"TV*") -> 0 | J5: =COUNTIFS(Errors!$F$3:$F$3008,$G5,Errors!$I$3:$I$3008,"<>TV*") -> 0 | K5: =COUNTIFS(Errors!$F$3:$F$3008,$G5,Errors!$Q$3:$Q$3008,"yes") -> 0 | N5: =COUNTIFS(Errors!$O$3:$O$3008,"Yes",Errors!$F$3:$F$3008,$M5)+COUNTIFS(Errors!$P$3:$P$3008,"Yes",Errors!$F$3:$F$3008,$M5) -> 0 | O5: =COUNTIFS(Errors!$O$3:$O$3008,"Yes",Errors!$F$3:$F$3008,$M5,Errors!$I$3:$I$3008,"TV*")+COUNTIFS(Errors!$P$3:$P$3008,"Yes",Errors!$F$3:$F$3008,$M5,Errors!$I$3:$I$3008,"TV*") -> 0 | P5: =COUNTIFS(Errors!$O$3:$O$3008,"Yes",Errors!$F$3:$F$3008,$M5,Errors!$I$3:$I$3008,"<>TV*")+COUNTIFS(Errors!$P$3:$P$3008,"Yes",Errors!$F$3:$F$3008,$M5,Errors!$I$3:$I$3008,"<>TV*") -> 0 | Q5: =COUNTIFS(Errors!$F$3:$F$3008,$M5,Errors!$O$3:$O$3008,"yes") -> 0 | R5: =COUNTIFS(Errors!$F$3:$F$3008,$M5,Errors!$P$3:$P$3008,"yes") -> 0 | AF5: =COUNTIFS(Errors!$F:$F,Analysis!$AE34,Errors!$D:$D,Analysis!$AF$2) -> 0 | AG5: =COUNTIFS(Errors!$F:$F,Analysis!$AE34,Errors!$D:$D,Analysis!$AG$2) -> 0 | AH5: =COUNTIFS(Errors!$F:$F,Analysis!$AE34,Errors!$D:$D,Analysis!$AH$2) -> 0 | AI5: =COUNTIFS(Errors!$F:$F,Analysis!$AE34,Errors!$D:$D,Analysis!$AI$2) -> 0 | AJ5: =COUNTIFS(Errors!$F:$F,Analysis!$AE34,Errors!$D:$D,Analysis!$AJ$2) -> 0 | AK5: =COUNTIFS(Errors!$F:$F,Analysis!$AE34,Errors!$D:$D,Analysis!$AK$2) -> 0 | AL5: =COUNTIFS(Errors!$F:$F,Analysis!$AE34,Errors!$D:$D,Analysis!$AL$2) -> 0 | AM5: =COUNTIFS(Errors!$F:$F,Analysis!$AE34,Errors!$D:$D,Analysis!$AM$2) -> 0 | AN5: =COUNTIFS(Errors!$F:$F,Analysis!$AE34,Errors!$D:$D,Analysis!$AN$2) -> 0 | AO5: =COUNTIFS(Errors!$F:$F,Analysis!$AE34,Errors!$D:$D,Analysis!$AO$2) -> 0 | AP5: =COUNTIFS(Errors!$F:$F,Analysis!$AE34,Errors!$D:$D,Analysis!$AP$2) -> 0 | AQ5: =COUNTIFS(Errors!$F:$F,Analysis!$AE34,Errors!$D:$D,Analysis!$AQ$2) -> 0 | AR5: =COUNTIFS(Errors!$F:$F,Analysis!$AE34,Errors!$D:$D,Analysis!$AR$2) -> 0 | AS5: =COUNTIFS(Errors!$F:$F,Analysis!$AE34,Errors!$D:$D,Analysis!$AS$2) -> 0 | AT5: =COUNTIFS(Errors!$F:$F,Analysis!$AE34,Errors!$D:$D,Analysis!$AT$2) -> 0 | AU5: =COUNTIFS(Errors!$F:$F,Analysis!$AE34,Errors!$D:$D,Analysis!$AU$2) -> 0 | AV5: =COUNTIFS(Errors!$F:$F,Analysis!$AE34,Errors!$D:$D,Analysis!$AV$2) -> 0 | AW5: =COUNTIFS(Errors!$F:$F,Analysis!$AE34,Errors!$D:$D,Analysis!$AW$2) -> 0 | AX5: =COUNTIFS(Errors!$F:$F,Analysis!$AE34,Errors!$D:$D,Analysis!$AX$2) -> 0 | AY5: =COUNTIFS(Errors!$F:$F,Analysis!$AE34,Errors!$D:$D,Analysis!$AY$2) -> 0 | AZ5: =COUNTIFS(Errors!$F:$F,Analysis!$AE34,Errors!$D:$D,Analysis!$AZ$2) -> 0 | BA5: =COUNTIFS(Errors!$F:$F,Analysis!$AE34,Errors!$D:$D,Analysis!$BA$2) -> 0 | BB5: =COUNTIFS(Errors!$F:$F,Analysis!$AE34,Errors!$D:$D,Analysis!$BB$2) -> 0 | BC5: =COUNTIFS(Errors!$F:$F,Analysis!$AE34,Errors!$D:$D,Analysis!$BC$2) -> 0 | BD5: =COUNTIFS(Errors!$F:$F,Analysis!$AE34,Errors!$D:$D,Analysis!$BD$2) -> 0 | BE5: =COUNTIFS(Errors!$F:$F,Analysis!$AE34,Errors!$D:$D,Analysis!$BE$2) -> 0 | BF5: =COUNTIFS(Errors!$F:$F,Analysis!$AE34,Errors!$D:$D,Analysis!$BF$2) -> 0 | BG5: =COUNTIFS(Errors!$F:$F,Analysis!$AE34,Errors!$D:$D,Analysis!$BG$2) -> 0 | BH5: =COUNTIFS(Errors!$F:$F,Analysis!$AE34,Errors!$D:$D,Analysis!$BH$2) -> 0 | BI5: =COUNTIFS(Errors!$F:$F,Analysis!$AE34,Errors!$D:$D,Analysis!$BI$2) -> 0 | BJ5: =COUNTIFS(Errors!$F:$F,Analysis!$AE34,Errors!$D:$D,Analysis!$BJ$2) -> 0 | BL5: =SUM(AF5:BJ5) -> 0 | BN5: =AVERAGE(AF5:BJ5) -> 0 | BO5: Baccarat_E3 | BS5: Baccarat_E3 | BT5: =COUNTIFS(Errors!$D:$D,Analysis!BT$1,Errors!$F:$F,Analysis!$BS5,Errors!$O:$O,"YES") -> 0 | BU5: =COUNTIFS(Errors!$D:$D,Analysis!BU$1,Errors!$F:$F,Analysis!$BS5,Errors!$O:$O,"YES") -> 0 | BV5: =COUNTIFS(Errors!$D:$D,Analysis!BV$1,Errors!$F:$F,Analysis!$BS5,Errors!$O:$O,"YES") -> 0 | BW5: =COUNTIFS(Errors!$D:$D,Analysis!BW$1,Errors!$F:$F,Analysis!$BS5,Errors!$O:$O,"YES") -> 0 | BX5: =COUNTIFS(Errors!$D:$D,Analysis!BX$1,Errors!$F:$F,Analysis!$BS5,Errors!$O:$O,"YES") -> 0 | BY5: =COUNTIFS(Errors!$D:$D,Analysis!BY$1,Errors!$F:$F,Analysis!$BS5,Errors!$O:$O,"YES") -> 0 | BZ5: =COUNTIFS(Errors!$D:$D,Analysis!BZ$1,Errors!$F:$F,Analysis!$BS5,Errors!$O:$O,"YES") -> 0 | CA5: =COUNTIFS(Errors!$D:$D,Analysis!CA$1,Errors!$F:$F,Analysis!$BS5,Errors!$O:$O,"YES") -> 0 | ... CX5: =COUNTIFS(Errors!$D:$D,Analysis!CX$1,Errors!$F:$F,Analysis!$BS5,Errors!$O:$O,"YES") -> 0 | CZ5: =SUM(BT5:CX5) -> 0 | DB5: =AVERAGE(BT5:CX5) -> 0 | DC5: Baccarat_E3
A6: TV-2 | B6: =COUNTIF(Errors!$I$3:$I$3008,$A6) -> 0 | C6: =COUNTIFS(Errors!$I$3:$I$3008,$A6,Errors!$J$3:$J$3008,"Bacc") -> 0 | D6: =COUNTIFS(Errors!$I$3:$I$3008,$A6,Errors!$J$3:$J$3008,"Rou") -> 0 | E6: =COUNTIFS(Errors!$I$3:$I$3008,$A6,Errors!$J$3:$J$3008,"Sic Bo") -> 0 | H6: =COUNTIF(Errors!$F$3:$F$3008,$G6) -> 0 | I6: =COUNTIFS(Errors!$F$3:$F$3008,$G6,Errors!$I$3:$I$3008,"TV*") -> 0 | J6: =COUNTIFS(Errors!$F$3:$F$3008,$G6,Errors!$I$3:$I$3008,"<>TV*") -> 0 | K6: =COUNTIFS(Errors!$F$3:$F$3008,$G6,Errors!$Q$3:$Q$3008,"yes") -> 0 | N6: =COUNTIFS(Errors!$O$3:$O$3008,"Yes",Errors!$F$3:$F$3008,$M6)+COUNTIFS(Errors!$P$3:$P$3008,"Yes",Errors!$F$3:$F$3008,$M6) -> 0 | O6: =COUNTIFS(Errors!$O$3:$O$3008,"Yes",Errors!$F$3:$F$3008,$M6,Errors!$I$3:$I$3008,"TV*")+COUNTIFS(Errors!$P$3:$P$3008,"Yes",Errors!$F$3:$F$3008,$M6,Errors!$I$3:$I$3008,"TV*") -> 0 | P6: =COUNTIFS(Errors!$O$3:$O$3008,"Yes",Errors!$F$3:$F$3008,$M6,Errors!$I$3:$I$3008,"<>TV*")+COUNTIFS(Errors!$P$3:$P$3008,"Yes",Errors!$F$3:$F$3008,$M6,Errors!$I$3:$I$3008,"<>TV*") -> 0 | Q6: =COUNTIFS(Errors!$F$3:$F$3008,$M6,Errors!$O$3:$O$3008,"yes") -> 0 | R6: =COUNTIFS(Errors!$F$3:$F$3008,$M6,Errors!$P$3:$P$3008,"yes") -> 0 | AF6: =COUNTIFS(Errors!$F:$F,Analysis!$AE35,Errors!$D:$D,Analysis!$AF$2) -> 0 | AG6: =COUNTIFS(Errors!$F:$F,Analysis!$AE35,Errors!$D:$D,Analysis!$AG$2) -> 0 | AH6: =COUNTIFS(Errors!$F:$F,Analysis!$AE35,Errors!$D:$D,Analysis!$AH$2) -> 0 | AI6: =COUNTIFS(Errors!$F:$F,Analysis!$AE35,Errors!$D:$D,Analysis!$AI$2) -> 0 | AJ6: =COUNTIFS(Errors!$F:$F,Analysis!$AE35,Errors!$D:$D,Analysis!$AJ$2) -> 0 | AK6: =COUNTIFS(Errors!$F:$F,Analysis!$AE35,Errors!$D:$D,Analysis!$AK$2) -> 0 | AL6: =COUNTIFS(Errors!$F:$F,Analysis!$AE35,Errors!$D:$D,Analysis!$AL$2) -> 0 | AM6: =COUNTIFS(Errors!$F:$F,Analysis!$AE35,Errors!$D:$D,Analysis!$AM$2) -> 0 | AN6: =COUNTIFS(Errors!$F:$F,Analysis!$AE35,Errors!$D:$D,Analysis!$AN$2) -> 0 | AO6: =COUNTIFS(Errors!$F:$F,Analysis!$AE35,Errors!$D:$D,Analysis!$AO$2) -> 0 | AP6: =COUNTIFS(Errors!$F:$F,Analysis!$AE35,Errors!$D:$D,Analysis!$AP$2) -> 0 | AQ6: =COUNTIFS(Errors!$F:$F,Analysis!$AE35,Errors!$D:$D,Analysis!$AQ$2) -> 0 | AR6: =COUNTIFS(Errors!$F:$F,Analysis!$AE35,Errors!$D:$D,Analysis!$AR$2) -> 0 | AS6: =COUNTIFS(Errors!$F:$F,Analysis!$AE35,Errors!$D:$D,Analysis!$AS$2) -> 0 | AT6: =COUNTIFS(Errors!$F:$F,Analysis!$AE35,Errors!$D:$D,Analysis!$AT$2) -> 0 | AU6: =COUNTIFS(Errors!$F:$F,Analysis!$AE35,Errors!$D:$D,Analysis!$AU$2) -> 0 | AV6: =COUNTIFS(Errors!$F:$F,Analysis!$AE35,Errors!$D:$D,Analysis!$AV$2) -> 0 | AW6: =COUNTIFS(Errors!$F:$F,Analysis!$AE35,Errors!$D:$D,Analysis!$AW$2) -> 0 | AX6: =COUNTIFS(Errors!$F:$F,Analysis!$AE35,Errors!$D:$D,Analysis!$AX$2) -> 0 | AY6: =COUNTIFS(Errors!$F:$F,Analysis!$AE35,Errors!$D:$D,Analysis!$AY$2) -> 0 | AZ6: =COUNTIFS(Errors!$F:$F,Analysis!$AE35,Errors!$D:$D,Analysis!$AZ$2) -> 0 | BA6: =COUNTIFS(Errors!$F:$F,Analysis!$AE35,Errors!$D:$D,Analysis!$BA$2) -> 0 | BB6: =COUNTIFS(Errors!$F:$F,Analysis!$AE35,Errors!$D:$D,Analysis!$BB$2) -> 0 | BC6: =COUNTIFS(Errors!$F:$F,Analysis!$AE35,Errors!$D:$D,Analysis!$BC$2) -> 0 | BD6: =COUNTIFS(Errors!$F:$F,Analysis!$AE35,Errors!$D:$D,Analysis!$BD$2) -> 0 | BE6: =COUNTIFS(Errors!$F:$F,Analysis!$AE35,Errors!$D:$D,Analysis!$BE$2) -> 0 | BF6: =COUNTIFS(Errors!$F:$F,Analysis!$AE35,Errors!$D:$D,Analysis!$BF$2) -> 0 | BG6: =COUNTIFS(Errors!$F:$F,Analysis!$AE35,Errors!$D:$D,Analysis!$BG$2) -> 0 | BH6: =COUNTIFS(Errors!$F:$F,Analysis!$AE35,Errors!$D:$D,Analysis!$BH$2) -> 0 | BI6: =COUNTIFS(Errors!$F:$F,Analysis!$AE35,Errors!$D:$D,Analysis!$BI$2) -> 0 | BJ6: =COUNTIFS(Errors!$F:$F,Analysis!$AE35,Errors!$D:$D,Analysis!$BJ$2) -> 0 | BL6: =SUM(AF6:BJ6) -> 0 | BN6: =AVERAGE(AF6:BJ6) -> 0 | BO6: Baccarat_E4 | BS6: Baccarat_E4 | BT6: =COUNTIFS(Errors!$D:$D,Analysis!BT$1,Errors!$F:$F,Analysis!$BS6,Errors!$O:$O,"YES") -> 0 | BU6: =COUNTIFS(Errors!$D:$D,Analysis!BU$1,Errors!$F:$F,Analysis!$BS6,Errors!$O:$O,"YES") -> 0 | BV6: =COUNTIFS(Errors!$D:$D,Analysis!BV$1,Errors!$F:$F,Analysis!$BS6,Errors!$O:$O,"YES") -> 0 | BW6: =COUNTIFS(Errors!$D:$D,Analysis!BW$1,Errors!$F:$F,Analysis!$BS6,Errors!$O:$O,"YES") -> 0 | BX6: =COUNTIFS(Errors!$D:$D,Analysis!BX$1,Errors!$F:$F,Analysis!$BS6,Errors!$O:$O,"YES") -> 0 | BY6: =COUNTIFS(Errors!$D:$D,Analysis!BY$1,Errors!$F:$F,Analysis!$BS6,Errors!$O:$O,"YES") -> 0 | BZ6: =COUNTIFS(Errors!$D:$D,Analysis!BZ$1,Errors!$F:$F,Analysis!$BS6,Errors!$O:$O,"YES") -> 0 | CA6: =COUNTIFS(Errors!$D:$D,Analysis!CA$1,Errors!$F:$F,Analysis!$BS6,Errors!$O:$O,"YES") -> 0 | ... CX6: =COUNTIFS(Errors!$D:$D,Analysis!CX$1,Errors!$F:$F,Analysis!$BS6,Errors!$O:$O,"YES") -> 0 | CZ6: =SUM(BT6:CX6) -> 0 | DB6: =AVERAGE(BT6:CX6) -> 0 | DC6: Baccarat_E4
A7: TV-3 | B7: =COUNTIF(Errors!$I$3:$I$3008,$A7) -> 0 | C7: =COUNTIFS(Errors!$I$3:$I$3008,$A7,Errors!$J$3:$J$3008,"Bacc") -> 0 | D7: =COUNTIFS(Errors!$I$3:$I$3008,$A7,Errors!$J$3:$J$3008,"Rou") -> 0 | E7: =COUNTIFS(Errors!$I$3:$I$3008,$A7,Errors!$J$3:$J$3008,"Sic Bo") -> 0 | H7: =COUNTIF(Errors!$F$3:$F$3008,$G7) -> 0 | I7: =COUNTIFS(Errors!$F$3:$F$3008,$G7,Errors!$I$3:$I$3008,"TV*") -> 0 | J7: =COUNTIFS(Errors!$F$3:$F$3008,$G7,Errors!$I$3:$I$3008,"<>TV*") -> 0 | K7: =COUNTIFS(Errors!$F$3:$F$3008,$G7,Errors!$Q$3:$Q$3008,"yes") -> 0 | N7: =COUNTIFS(Errors!$O$3:$O$3008,"Yes",Errors!$F$3:$F$3008,$M7)+COUNTIFS(Errors!$P$3:$P$3008,"Yes",Errors!$F$3:$F$3008,$M7) -> 0 | O7: =COUNTIFS(Errors!$O$3:$O$3008,"Yes",Errors!$F$3:$F$3008,$M7,Errors!$I$3:$I$3008,"TV*")+COUNTIFS(Errors!$P$3:$P$3008,"Yes",Errors!$F$3:$F$3008,$M7,Errors!$I$3:$I$3008,"TV*") -> 0 | P7: =COUNTIFS(Errors!$O$3:$O$3008,"Yes",Errors!$F$3:$F$3008,$M7,Errors!$I$3:$I$3008,"<>TV*")+COUNTIFS(Errors!$P$3:$P$3008,"Yes",Errors!$F$3:$F$3008,$M7,Errors!$I$3:$I$3008,"<>TV*") -> 0 | Q7: =COUNTIFS(Errors!$F$3:$F$3008,$M7,Errors!$O$3:$O$3008,"yes") -> 0 | R7: =COUNTIFS(Errors!$F$3:$F$3008,$M7,Errors!$P$3:$P$3008,"yes") -> 0 | AF7: =COUNTIFS(Errors!$F:$F,Analysis!$AE36,Errors!$D:$D,Analysis!$AF$2) -> 0 | AG7: =COUNTIFS(Errors!$F:$F,Analysis!$AE36,Errors!$D:$D,Analysis!$AG$2) -> 0 | AH7: =COUNTIFS(Errors!$F:$F,Analysis!$AE36,Errors!$D:$D,Analysis!$AH$2) -> 0 | AI7: =COUNTIFS(Errors!$F:$F,Analysis!$AE36,Errors!$D:$D,Analysis!$AI$2) -> 0 | AJ7: =COUNTIFS(Errors!$F:$F,Analysis!$AE36,Errors!$D:$D,Analysis!$AJ$2) -> 0 | AK7: =COUNTIFS(Errors!$F:$F,Analysis!$AE36,Errors!$D:$D,Analysis!$AK$2) -> 0 | AL7: =COUNTIFS(Errors!$F:$F,Analysis!$AE36,Errors!$D:$D,Analysis!$AL$2) -> 0 | AM7: =COUNTIFS(Errors!$F:$F,Analysis!$AE36,Errors!$D:$D,Analysis!$AM$2) -> 0 | AN7: =COUNTIFS(Errors!$F:$F,Analysis!$AE36,Errors!$D:$D,Analysis!$AN$2) -> 0 | AO7: =COUNTIFS(Errors!$F:$F,Analysis!$AE36,Errors!$D:$D,Analysis!$AO$2) -> 0 | AP7: =COUNTIFS(Errors!$F:$F,Analysis!$AE36,Errors!$D:$D,Analysis!$AP$2) -> 0 | AQ7: =COUNTIFS(Errors!$F:$F,Analysis!$AE36,Errors!$D:$D,Analysis!$AQ$2) -> 0 | AR7: =COUNTIFS(Errors!$F:$F,Analysis!$AE36,Errors!$D:$D,Analysis!$AR$2) -> 0 | AS7: =COUNTIFS(Errors!$F:$F,Analysis!$AE36,Errors!$D:$D,Analysis!$AS$2) -> 0 | AT7: =COUNTIFS(Errors!$F:$F,Analysis!$AE36,Errors!$D:$D,Analysis!$AT$2) -> 0 | AU7: =COUNTIFS(Errors!$F:$F,Analysis!$AE36,Errors!$D:$D,Analysis!$AU$2) -> 0 | AV7: =COUNTIFS(Errors!$F:$F,Analysis!$AE36,Errors!$D:$D,Analysis!$AV$2) -> 0 | AW7: =COUNTIFS(Errors!$F:$F,Analysis!$AE36,Errors!$D:$D,Analysis!$AW$2) -> 0 | AX7: =COUNTIFS(Errors!$F:$F,Analysis!$AE36,Errors!$D:$D,Analysis!$AX$2) -> 0 | AY7: =COUNTIFS(Errors!$F:$F,Analysis!$AE36,Errors!$D:$D,Analysis!$AY$2) -> 0 | AZ7: =COUNTIFS(Errors!$F:$F,Analysis!$AE36,Errors!$D:$D,Analysis!$AZ$2) -> 0 | BA7: =COUNTIFS(Errors!$F:$F,Analysis!$AE36,Errors!$D:$D,Analysis!$BA$2) -> 0 | BB7: =COUNTIFS(Errors!$F:$F,Analysis!$AE36,Errors!$D:$D,Analysis!$BB$2) -> 0 | BC7: =COUNTIFS(Errors!$F:$F,Analysis!$AE36,Errors!$D:$D,Analysis!$BC$2) -> 0 | BD7: =COUNTIFS(Errors!$F:$F,Analysis!$AE36,Errors!$D:$D,Analysis!$BD$2) -> 0 | BE7: =COUNTIFS(Errors!$F:$F,Analysis!$AE36,Errors!$D:$D,Analysis!$BE$2) -> 0 | BF7: =COUNTIFS(Errors!$F:$F,Analysis!$AE36,Errors!$D:$D,Analysis!$BF$2) -> 0 | BG7: =COUNTIFS(Errors!$F:$F,Analysis!$AE36,Errors!$D:$D,Analysis!$BG$2) -> 0 | BH7: =COUNTIFS(Errors!$F:$F,Analysis!$AE36,Errors!$D:$D,Analysis!$BH$2) -> 0 | BI7: =COUNTIFS(Errors!$F:$F,Analysis!$AE36,Errors!$D:$D,Analysis!$BI$2) -> 0 | BJ7: =COUNTIFS(Errors!$F:$F,Analysis!$AE36,Errors!$D:$D,Analysis!$BJ$2) -> 0 | BL7: =SUM(AF7:BJ7) -> 0 | BN7: =AVERAGE(AF7:BJ7) -> 0 | BO7: Baccarat_E5 | BS7: Baccarat_E5 | BT7: =COUNTIFS(Errors!$D:$D,Analysis!BT$1,Errors!$F:$F,Analysis!$BS7,Errors!$O:$O,"YES") -> 0 | BU7: =COUNTIFS(Errors!$D:$D,Analysis!BU$1,Errors!$F:$F,Analysis!$BS7,Errors!$O:$O,"YES") -> 0 | BV7: =COUNTIFS(Errors!$D:$D,Analysis!BV$1,Errors!$F:$F,Analysis!$BS7,Errors!$O:$O,"YES") -> 0 | BW7: =COUNTIFS(Errors!$D:$D,Analysis!BW$1,Errors!$F:$F,Analysis!$BS7,Errors!$O:$O,"YES") -> 0 | BX7: =COUNTIFS(Errors!$D:$D,Analysis!BX$1,Errors!$F:$F,Analysis!$BS7,Errors!$O:$O,"YES") -> 0 | BY7: =COUNTIFS(Errors!$D:$D,Analysis!BY$1,Errors!$F:$F,Analysis!$BS7,Errors!$O:$O,"YES") -> 0 | BZ7: =COUNTIFS(Errors!$D:$D,Analysis!BZ$1,Errors!$F:$F,Analysis!$BS7,Errors!$O:$O,"YES") -> 0 | CA7: =COUNTIFS(Errors!$D:$D,Analysis!CA$1,Errors!$F:$F,Analysis!$BS7,Errors!$O:$O,"YES") -> 0 | ... CX7: =COUNTIFS(Errors!$D:$D,Analysis!CX$1,Errors!$F:$F,Analysis!$BS7,Errors!$O:$O,"YES") -> 0 | CZ7: =SUM(BT7:CX7) -> 0 | DB7: =AVERAGE(BT7:CX7) -> 0 | DC7: Baccarat_E5
A8: TV-HUM | B8: =COUNTIF(Errors!$I$3:$I$3008,$A8) -> 1 | C8: =COUNTIFS(Errors!$I$3:$I$3008,$A8,Errors!$J$3:$J$3008,"Bacc") -> 0 | D8: =COUNTIFS(Errors!$I$3:$I$3008,$A8,Errors!$J$3:$J$3008,"Rou") -> 1 | E8: =COUNTIFS(Errors!$I$3:$I$3008,$A8,Errors!$J$3:$J$3008,"Sic Bo") -> 0 | H8: =COUNTIF(Errors!$F$3:$F$3008,$G8) -> 0 | I8: =COUNTIFS(Errors!$F$3:$F$3008,$G8,Errors!$I$3:$I$3008,"TV*") -> 0 | J8: =COUNTIFS(Errors!$F$3:$F$3008,$G8,Errors!$I$3:$I$3008,"<>TV*") -> 0 | K8: =COUNTIFS(Errors!$F$3:$F$3008,$G8,Errors!$Q$3:$Q$3008,"yes") -> 0 | N8: =COUNTIFS(Errors!$O$3:$O$3008,"Yes",Errors!$F$3:$F$3008,$M8)+COUNTIFS(Errors!$P$3:$P$3008,"Yes",Errors!$F$3:$F$3008,$M8) -> 0 | O8: =COUNTIFS(Errors!$O$3:$O$3008,"Yes",Errors!$F$3:$F$3008,$M8,Errors!$I$3:$I$3008,"TV*")+COUNTIFS(Errors!$P$3:$P$3008,"Yes",Errors!$F$3:$F$3008,$M8,Errors!$I$3:$I$3008,"TV*") -> 0 | P8: =COUNTIFS(Errors!$O$3:$O$3008,"Yes",Errors!$F$3:$F$3008,$M8,Errors!$I$3:$I$3008,"<>TV*")+COUNTIFS(Errors!$P$3:$P$3008,"Yes",Errors!$F$3:$F$3008,$M8,Errors!$I$3:$I$3008,"<>TV*") -> 0 | Q8: =COUNTIFS(Errors!$F$3:$F$3008,$M8,Errors!$O$3:$O$3008,"yes") -> 0 | R8: =COUNTIFS(Errors!$F$3:$F$3008,$M8,Errors!$P$3:$P$3008,"yes") -> 0 | AF8: =COUNTIFS(Errors!$F:$F,Analysis!$AE37,Errors!$D:$D,Analysis!$AF$2) -> 0 | AG8: =COUNTIFS(Errors!$F:$F,Analysis!$AE37,Errors!$D:$D,Analysis!$AG$2) -> 0 | AH8: =COUNTIFS(Errors!$F:$F,Analysis!$AE37,Errors!$D:$D,Analysis!$AH$2) -> 0 | AI8: =COUNTIFS(Errors!$F:$F,Analysis!$AE37,Errors!$D:$D,Analysis!$AI$2) -> 0 | AJ8: =COUNTIFS(Errors!$F:$F,Analysis!$AE37,Errors!$D:$D,Analysis!$AJ$2) -> 0 | AK8: =COUNTIFS(Errors!$F:$F,Analysis!$AE37,Errors!$D:$D,Analysis!$AK$2) -> 0 | AL8: =COUNTIFS(Errors!$F:$F,Analysis!$AE37,Errors!$D:$D,Analysis!$AL$2) -> 0 | AM8: =COUNTIFS(Errors!$F:$F,Analysis!$AE37,Errors!$D:$D,Analysis!$AM$2) -> 0 | AN8: =COUNTIFS(Errors!$F:$F,Analysis!$AE37,Errors!$D:$D,Analysis!$AN$2) -> 0 | AO8: =COUNTIFS(Errors!$F:$F,Analysis!$AE37,Errors!$D:$D,Analysis!$AO$2) -> 0 | AP8: =COUNTIFS(Errors!$F:$F,Analysis!$AE37,Errors!$D:$D,Analysis!$AP$2) -> 0 | AQ8: =COUNTIFS(Errors!$F:$F,Analysis!$AE37,Errors!$D:$D,Analysis!$AQ$2) -> 0 | AR8: =COUNTIFS(Errors!$F:$F,Analysis!$AE37,Errors!$D:$D,Analysis!$AR$2) -> 0 | AS8: =COUNTIFS(Errors!$F:$F,Analysis!$AE37,Errors!$D:$D,Analysis!$AS$2) -> 0 | AT8: =COUNTIFS(Errors!$F:$F,Analysis!$AE37,Errors!$D:$D,Analysis!$AT$2) -> 0 | AU8: =COUNTIFS(Errors!$F:$F,Analysis!$AE37,Errors!$D:$D,Analysis!$AU$2) -> 0 | AV8: =COUNTIFS(Errors!$F:$F,Analysis!$AE37,Errors!$D:$D,Analysis!$AV$2) -> 0 | AW8: =COUNTIFS(Errors!$F:$F,Analysis!$AE37,Errors!$D:$D,Analysis!$AW$2) -> 0 | AX8: =COUNTIFS(Errors!$F:$F,Analysis!$AE37,Errors!$D:$D,Analysis!$AX$2) -> 0 | AY8: =COUNTIFS(Errors!$F:$F,Analysis!$AE37,Errors!$D:$D,Analysis!$AY$2) -> 0 | AZ8: =COUNTIFS(Errors!$F:$F,Analysis!$AE37,Errors!$D:$D,Analysis!$AZ$2) -> 0 | BA8: =COUNTIFS(Errors!$F:$F,Analysis!$AE37,Errors!$D:$D,Analysis!$BA$2) -> 0 | BB8: =COUNTIFS(Errors!$F:$F,Analysis!$AE37,Errors!$D:$D,Analysis!$BB$2) -> 0 | BC8: =COUNTIFS(Errors!$F:$F,Analysis!$AE37,Errors!$D:$D,Analysis!$BC$2) -> 0 | BD8: =COUNTIFS(Errors!$F:$F,Analysis!$AE37,Errors!$D:$D,Analysis!$BD$2) -> 0 | BE8: =COUNTIFS(Errors!$F:$F,Analysis!$AE37,Errors!$D:$D,Analysis!$BE$2) -> 0 | BF8: =COUNTIFS(Errors!$F:$F,Analysis!$AE37,Errors!$D:$D,Analysis!$BF$2) -> 0 | BG8: =COUNTIFS(Errors!$F:$F,Analysis!$AE37,Errors!$D:$D,Analysis!$BG$2) -> 0 | BH8: =COUNTIFS(Errors!$F:$F,Analysis!$AE37,Errors!$D:$D,Analysis!$BH$2) -> 0 | BI8: =COUNTIFS(Errors!$F:$F,Analysis!$AE37,Errors!$D:$D,Analysis!$BI$2) -> 0 | BJ8: =COUNTIFS(Errors!$F:$F,Analysis!$AE37,Errors!$D:$D,Analysis!$BJ$2) -> 0 | BL8: =SUM(AF8:BJ8) -> 0 | BN8: =AVERAGE(AF8:BJ8) -> 0 | BO8: Baccarat_E6 | BS8: Baccarat_E6 | BT8: =COUNTIFS(Errors!$D:$D,Analysis!BT$1,Errors!$F:$F,Analysis!$BS8,Errors!$O:$O,"YES") -> 0 | BU8: =COUNTIFS(Errors!$D:$D,Analysis!BU$1,Errors!$F:$F,Analysis!$BS8,Errors!$O:$O,"YES") -> 0 | BV8: =COUNTIFS(Errors!$D:$D,Analysis!BV$1,Errors!$F:$F,Analysis!$BS8,Errors!$O:$O,"YES") -> 0 | BW8: =COUNTIFS(Errors!$D:$D,Analysis!BW$1,Errors!$F:$F,Analysis!$BS8,Errors!$O:$O,"YES") -> 0 | BX8: =COUNTIFS(Errors!$D:$D,Analysis!BX$1,Errors!$F:$F,Analysis!$BS8,Errors!$O:$O,"YES") -> 0 | BY8: =COUNTIFS(Errors!$D:$D,Analysis!BY$1,Errors!$F:$F,Analysis!$BS8,Errors!$O:$O,"YES") -> 0 | BZ8: =COUNTIFS(Errors!$D:$D,Analysis!BZ$1,Errors!$F:$F,Analysis!$BS8,Errors!$O:$O,"YES") -> 0 | CA8: =COUNTIFS(Errors!$D:$D,Analysis!CA$1,Errors!$F:$F,Analysis!$BS8,Errors!$O:$O,"YES") -> 0 | ... CX8: =COUNTIFS(Errors!$D:$D,Analysis!CX$1,Errors!$F:$F,Analysis!$BS8,Errors!$O:$O,"YES") -> 0 | CZ8: =SUM(BT8:CX8) -> 0 | DB8: =AVERAGE(BT8:CX8) -> 0 | DC8: Baccarat_E6
A9: TV-COM | B9: =COUNTIF(Errors!$I$3:$I$3008,$A9) -> 1 | C9: =COUNTIFS(Errors!$I$3:$I$3008,$A9,Errors!$J$3:$J$3008,"Bacc") -> 1 | D9: =COUNTIFS(Errors!$I$3:$I$3008,$A9,Errors!$J$3:$J$3008,"Rou") -> 0 | E9: =COUNTIFS(Errors!$I$3:$I$3008,$A9,Errors!$J$3:$J$3008,"Sic Bo") -> 0 | H9: =COUNTIF(Errors!$F$3:$F$3008,$G9) -> 0 | I9: =COUNTIFS(Errors!$F$3:$F$3008,$G9,Errors!$I$3:$I$3008,"TV*") -> 0 | J9: =COUNTIFS(Errors!$F$3:$F$3008,$G9,Errors!$I$3:$I$3008,"<>TV*") -> 0 | K9: =COUNTIFS(Errors!$F$3:$F$3008,$G9,Errors!$Q$3:$Q$3008,"yes") -> 0 | N9: =COUNTIFS(Errors!$O$3:$O$3008,"Yes",Errors!$F$3:$F$3008,$M9)+COUNTIFS(Errors!$P$3:$P$3008,"Yes",Errors!$F$3:$F$3008,$M9) -> 0 | O9: =COUNTIFS(Errors!$O$3:$O$3008,"Yes",Errors!$F$3:$F$3008,$M9,Errors!$I$3:$I$3008,"TV*")+COUNTIFS(Errors!$P$3:$P$3008,"Yes",Errors!$F$3:$F$3008,$M9,Errors!$I$3:$I$3008,"TV*") -> 0 | P9: =COUNTIFS(Errors!$O$3:$O$3008,"Yes",Errors!$F$3:$F$3008,$M9,Errors!$I$3:$I$3008,"<>TV*")+COUNTIFS(Errors!$P$3:$P$3008,"Yes",Errors!$F$3:$F$3008,$M9,Errors!$I$3:$I$3008,"<>TV*") -> 0 | Q9: =COUNTIFS(Errors!$F$3:$F$3008,$M9,Errors!$O$3:$O$3008,"yes") -> 0 | R9: =COUNTIFS(Errors!$F$3:$F$3008,$M9,Errors!$P$3:$P$3008,"yes") -> 0 | AF9: =COUNTIFS(Errors!$F:$F,Analysis!$AE38,Errors!$D:$D,Analysis!$AF$2) -> 0 | AG9: =COUNTIFS(Errors!$F:$F,Analysis!$AE38,Errors!$D:$D,Analysis!$AG$2) -> 0 | AH9: =COUNTIFS(Errors!$F:$F,Analysis!$AE38,Errors!$D:$D,Analysis!$AH$2) -> 0 | AI9: =COUNTIFS(Errors!$F:$F,Analysis!$AE38,Errors!$D:$D,Analysis!$AI$2) -> 0 | AJ9: =COUNTIFS(Errors!$F:$F,Analysis!$AE38,Errors!$D:$D,Analysis!$AJ$2) -> 0 | AK9: =COUNTIFS(Errors!$F:$F,Analysis!$AE38,Errors!$D:$D,Analysis!$AK$2) -> 0 | AL9: =COUNTIFS(Errors!$F:$F,Analysis!$AE38,Errors!$D:$D,Analysis!$AL$2) -> 0 | AM9: =COUNTIFS(Errors!$F:$F,Analysis!$AE38,Errors!$D:$D,Analysis!$AM$2) -> 0 | AN9: =COUNTIFS(Errors!$F:$F,Analysis!$AE38,Errors!$D:$D,Analysis!$AN$2) -> 0 | AO9: =COUNTIFS(Errors!$F:$F,Analysis!$AE38,Errors!$D:$D,Analysis!$AO$2) -> 0 | AP9: =COUNTIFS(Errors!$F:$F,Analysis!$AE38,Errors!$D:$D,Analysis!$AP$2) -> 0 | AQ9: =COUNTIFS(Errors!$F:$F,Analysis!$AE38,Errors!$D:$D,Analysis!$AQ$2) -> 0 | AR9: =COUNTIFS(Errors!$F:$F,Analysis!$AE38,Errors!$D:$D,Analysis!$AR$2) -> 0 | AS9: =COUNTIFS(Errors!$F:$F,Analysis!$AE38,Errors!$D:$D,Analysis!$AS$2) -> 0 | AT9: =COUNTIFS(Errors!$F:$F,Analysis!$AE38,Errors!$D:$D,Analysis!$AT$2) -> 0 | AU9: =COUNTIFS(Errors!$F:$F,Analysis!$AE38,Errors!$D:$D,Analysis!$AU$2) -> 0 | AV9: =COUNTIFS(Errors!$F:$F,Analysis!$AE38,Errors!$D:$D,Analysis!$AV$2) -> 0 | AW9: =COUNTIFS(Errors!$F:$F,Analysis!$AE38,Errors!$D:$D,Analysis!$AW$2) -> 0 | AX9: =COUNTIFS(Errors!$F:$F,Analysis!$AE38,Errors!$D:$D,Analysis!$AX$2) -> 0 | AY9: =COUNTIFS(Errors!$F:$F,Analysis!$AE38,Errors!$D:$D,Analysis!$AY$2) -> 0 | AZ9: =COUNTIFS(Errors!$F:$F,Analysis!$AE38,Errors!$D:$D,Analysis!$AZ$2) -> 0 | BA9: =COUNTIFS(Errors!$F:$F,Analysis!$AE38,Errors!$D:$D,Analysis!$BA$2) -> 0 | BB9: =COUNTIFS(Errors!$F:$F,Analysis!$AE38,Errors!$D:$D,Analysis!$BB$2) -> 0 | BC9: =COUNTIFS(Errors!$F:$F,Analysis!$AE38,Errors!$D:$D,Analysis!$BC$2) -> 0 | BD9: =COUNTIFS(Errors!$F:$F,Analysis!$AE38,Errors!$D:$D,Analysis!$BD$2) -> 0 | BE9: =COUNTIFS(Errors!$F:$F,Analysis!$AE38,Errors!$D:$D,Analysis!$BE$2) -> 0 | BF9: =COUNTIFS(Errors!$F:$F,Analysis!$AE38,Errors!$D:$D,Analysis!$BF$2) -> 0 | BG9: =COUNTIFS(Errors!$F:$F,Analysis!$AE38,Errors!$D:$D,Analysis!$BG$2) -> 0 | BH9: =COUNTIFS(Errors!$F:$F,Analysis!$AE38,Errors!$D:$D,Analysis!$BH$2) -> 0 | BI9: =COUNTIFS(Errors!$F:$F,Analysis!$AE38,Errors!$D:$D,Analysis!$BI$2) -> 0 | BJ9: =COUNTIFS(Errors!$F:$F,Analysis!$AE38,Errors!$D:$D,Analysis!$BJ$2) -> 0 | BL9: =SUM(AF9:BJ9) -> 0 | BN9: =AVERAGE(AF9:BJ9) -> 0 | BO9: Baccarat_E7 | BS9: Baccarat_E7 | BT9: =COUNTIFS(Errors!$D:$D,Analysis!BT$1,Errors!$F:$F,Analysis!$BS9,Errors!$O:$O,"YES") -> 0 | BU9: =COUNTIFS(Errors!$D:$D,Analysis!BU$1,Errors!$F:$F,Analysis!$BS9,Errors!$O:$O,"YES") -> 0 | BV9: =COUNTIFS(Errors!$D:$D,Analysis!BV$1,Errors!$F:$F,Analysis!$BS9,Errors!$O:$O,"YES") -> 0 | BW9: =COUNTIFS(Errors!$D:$D,Analysis!BW$1,Errors!$F:$F,Analysis!$BS9,Errors!$O:$O,"YES") -> 0 | BX9: =COUNTIFS(Errors!$D:$D,Analysis!BX$1,Errors!$F:$F,Analysis!$BS9,Errors!$O:$O,"YES") -> 0 | BY9: =COUNTIFS(Errors!$D:$D,Analysis!BY$1,Errors!$F:$F,Analysis!$BS9,Errors!$O:$O,"YES") -> 0 | BZ9: =COUNTIFS(Errors!$D:$D,Analysis!BZ$1,Errors!$F:$F,Analysis!$BS9,Errors!$O:$O,"YES") -> 0 | CA9: =COUNTIFS(Errors!$D:$D,Analysis!CA$1,Errors!$F:$F,Analysis!$BS9,Errors!$O:$O,"YES") -> 0 | ... CX9: =COUNTIFS(Errors!$D:$D,Analysis!CX$1,Errors!$F:$F,Analysis!$BS9,Errors!$O:$O,"YES") -> 0 | CZ9: =SUM(BT9:CX9) -> 0 | DB9: =AVERAGE(BT9:CX9) -> 0 | DC9: Baccarat_E7
H10: =COUNTIF(Errors!$F$3:$F$3008,$G10) -> 0 | I10: =COUNTIFS(Errors!$F$3:$F$3008,$G10,Errors!$I$3:$I$3008,"TV*") -> 0 | J10: =COUNTIFS(Errors!$F$3:$F$3008,$G10,Errors!$I$3:$I$3008,"<>TV*") -> 0 | K10: =COUNTIFS(Errors!$F$3:$F$3008,$G10,Errors!$Q$3:$Q$3008,"yes") -> 0 | N10: =COUNTIFS(Errors!$O$3:$O$3008,"Yes",Errors!$F$3:$F$3008,$M10)+COUNTIFS(Errors!$P$3:$P$3008,"Yes",Errors!$F$3:$F$3008,$M10) -> 0 | O10: =COUNTIFS(Errors!$O$3:$O$3008,"Yes",Errors!$F$3:$F$3008,$M10,Errors!$I$3:$I$3008,"TV*")+COUNTIFS(Errors!$P$3:$P$3008,"Yes",Errors!$F$3:$F$3008,$M10,Errors!$I$3:$I$3008,"TV*") -> 0 | P10: =COUNTIFS(Errors!$O$3:$O$3008,"Yes",Errors!$F$3:$F$3008,$M10,Errors!$I$3:$I$3008,"<>TV*")+COUNTIFS(Errors!$P$3:$P$3008,"Yes",Errors!$F$3:$F$3008,$M10,Errors!$I$3:$I$3008,"<>TV*") -> 0 | Q10: =COUNTIFS(Errors!$F$3:$F$3008,$M10,Errors!$O$3:$O$3008,"yes") -> 0 | R10: =COUNTIFS(Errors!$F$3:$F$3008,$M10,Errors!$P$3:$P$3008,"yes") -> 0 | AF10: =COUNTIFS(Errors!$F:$F,Analysis!$AE39,Errors!$D:$D,Analysis!$AF$2) -> 0 | AG10: =COUNTIFS(Errors!$F:$F,Analysis!$AE39,Errors!$D:$D,Analysis!$AG$2) -> 0 | AH10: =COUNTIFS(Errors!$F:$F,Analysis!$AE39,Errors!$D:$D,Analysis!$AH$2) -> 0 | AI10: =COUNTIFS(Errors!$F:$F,Analysis!$AE39,Errors!$D:$D,Analysis!$AI$2) -> 0 | AJ10: =COUNTIFS(Errors!$F:$F,Analysis!$AE39,Errors!$D:$D,Analysis!$AJ$2) -> 0 | AK10: =COUNTIFS(Errors!$F:$F,Analysis!$AE39,Errors!$D:$D,Analysis!$AK$2) -> 0 | AL10: =COUNTIFS(Errors!$F:$F,Analysis!$AE39,Errors!$D:$D,Analysis!$AL$2) -> 0 | AM10: =COUNTIFS(Errors!$F:$F,Analysis!$AE39,Errors!$D:$D,Analysis!$AM$2) -> 0 | AN10: =COUNTIFS(Errors!$F:$F,Analysis!$AE39,Errors!$D:$D,Analysis!$AN$2) -> 0 | AO10: =COUNTIFS(Errors!$F:$F,Analysis!$AE39,Errors!$D:$D,Analysis!$AO$2) -> 0 | AP10: =COUNTIFS(Errors!$F:$F,Analysis!$AE39,Errors!$D:$D,Analysis!$AP$2) -> 0 | AQ10: =COUNTIFS(Errors!$F:$F,Analysis!$AE39,Errors!$D:$D,Analysis!$AQ$2) -> 0 | AR10: =COUNTIFS(Errors!$F:$F,Analysis!$AE39,Errors!$D:$D,Analysis!$AR$2) -> 0 | AS10: =COUNTIFS(Errors!$F:$F,Analysis!$AE39,Errors!$D:$D,Analysis!$AS$2) -> 0 | AT10: =COUNTIFS(Errors!$F:$F,Analysis!$AE39,Errors!$D:$D,Analysis!$AT$2) -> 0 | AU10: =COUNTIFS(Errors!$F:$F,Analysis!$AE39,Errors!$D:$D,Analysis!$AU$2) -> 0 | AV10: =COUNTIFS(Errors!$F:$F,Analysis!$AE39,Errors!$D:$D,Analysis!$AV$2) -> 0 | AW10: =COUNTIFS(Errors!$F:$F,Analysis!$AE39,Errors!$D:$D,Analysis!$AW$2) -> 0 | AX10: =COUNTIFS(Errors!$F:$F,Analysis!$AE39,Errors!$D:$D,Analysis!$AX$2) -> 0 | AY10: =COUNTIFS(Errors!$F:$F,Analysis!$AE39,Errors!$D:$D,Analysis!$AY$2) -> 0 | AZ10: =COUNTIFS(Errors!$F:$F,Analysis!$AE39,Errors!$D:$D,Analysis!$AZ$2) -> 0 | BA10: =COUNTIFS(Errors!$F:$F,Analysis!$AE39,Errors!$D:$D,Analysis!$BA$2) -> 0 | BB10: =COUNTIFS(Errors!$F:$F,Analysis!$AE39,Errors!$D:$D,Analysis!$BB$2) -> 0 | BC10: =COUNTIFS(Errors!$F:$F,Analysis!$AE39,Errors!$D:$D,Analysis!$BC$2) -> 0 | BD10: =COUNTIFS(Errors!$F:$F,Analysis!$AE39,Errors!$D:$D,Analysis!$BD$2) -> 0 | BE10: =COUNTIFS(Errors!$F:$F,Analysis!$AE39,Errors!$D:$D,Analysis!$BE$2) -> 0 | BF10: =COUNTIFS(Errors!$F:$F,Analysis!$AE39,Errors!$D:$D,Analysis!$BF$2) -> 0 | BG10: =COUNTIFS(Errors!$F:$F,Analysis!$AE39,Errors!$D:$D,Analysis!$BG$2) -> 0 | BH10: =COUNTIFS(Errors!$F:$F,Analysis!$AE39,Errors!$D:$D,Analysis!$BH$2) -> 0 | BI10: =COUNTIFS(Errors!$F:$F,Analysis!$AE39,Errors!$D:$D,Analysis!$BI$2) -> 0 | BJ10: =COUNTIFS(Errors!$F:$F,Analysis!$AE39,Errors!$D:$D,Analysis!$BJ$2) -> 0 | BL10: =SUM(AF10:BJ10) -> 0 | BN10: =AVERAGE(AF10:BJ10) -> 0 | BO10: Baccarat_E8 | BS10: Baccarat_E8 | BT10: =COUNTIFS(Errors!$D:$D,Analysis!BT$1,Errors!$F:$F,Analysis!$BS10,Errors!$O:$O,"YES") -> 0 | BU10: =COUNTIFS(Errors!$D:$D,Analysis!BU$1,Errors!$F:$F,Analysis!$BS10,Errors!$O:$O,"YES") -> 0 | BV10: =COUNTIFS(Errors!$D:$D,Analysis!BV$1,Errors!$F:$F,Analysis!$BS10,Errors!$O:$O,"YES") -> 0 | BW10: =COUNTIFS(Errors!$D:$D,Analysis!BW$1,Errors!$F:$F,Analysis!$BS10,Errors!$O:$O,"YES") -> 0 | BX10: =COUNTIFS(Errors!$D:$D,Analysis!BX$1,Errors!$F:$F,Analysis!$BS10,Errors!$O:$O,"YES") -> 0 | BY10: =COUNTIFS(Errors!$D:$D,Analysis!BY$1,Errors!$F:$F,Analysis!$BS10,Errors!$O:$O,"YES") -> 0 | BZ10: =COUNTIFS(Errors!$D:$D,Analysis!BZ$1,Errors!$F:$F,Analysis!$BS10,Errors!$O:$O,"YES") -> 0 | CA10: =COUNTIFS(Errors!$D:$D,Analysis!CA$1,Errors!$F:$F,Analysis!$BS10,Errors!$O:$O,"YES") -> 0 | ... CX10: =COUNTIFS(Errors!$D:$D,Analysis!CX$1,Errors!$F:$F,Analysis!$BS10,Errors!$O:$O,"YES") -> 0 | CZ10: =SUM(BT10:CX10) -> 0 | DB10: =AVERAGE(BT10:CX10) -> 0 | DC10: Baccarat_E8
H11: =COUNTIF(Errors!$F$3:$F$3008,$G11) -> 0 | I11: =COUNTIFS(Errors!$F$3:$F$3008,$G11,Errors!$I$3:$I$3008,"TV*") -> 0 | J11: =COUNTIFS(Errors!$F$3:$F$3008,$G11,Errors!$I$3:$I$3008,"<>TV*") -> 0 | K11: =COUNTIFS(Errors!$F$3:$F$3008,$G11,Errors!$Q$3:$Q$3008,"yes") -> 0 | N11: =COUNTIFS(Errors!$O$3:$O$3008,"Yes",Errors!$F$3:$F$3008,$M11)+COUNTIFS(Errors!$P$3:$P$3008,"Yes",Errors!$F$3:$F$3008,$M11) -> 0 | O11: =COUNTIFS(Errors!$O$3:$O$3008,"Yes",Errors!$F$3:$F$3008,$M11,Errors!$I$3:$I$3008,"TV*")+COUNTIFS(Errors!$P$3:$P$3008,"Yes",Errors!$F$3:$F$3008,$M11,Errors!$I$3:$I$3008,"TV*") -> 0 | P11: =COUNTIFS(Errors!$O$3:$O$3008,"Yes",Errors!$F$3:$F$3008,$M11,Errors!$I$3:$I$3008,"<>TV*")+COUNTIFS(Errors!$P$3:$P$3008,"Yes",Errors!$F$3:$F$3008,$M11,Errors!$I$3:$I$3008,"<>TV*") -> 0 | Q11: =COUNTIFS(Errors!$F$3:$F$3008,$M11,Errors!$O$3:$O$3008,"yes") -> 0 | R11: =COUNTIFS(Errors!$F$3:$F$3008,$M11,Errors!$P$3:$P$3008,"yes") -> 0 | AF11: =COUNTIFS(Errors!$F:$F,Analysis!$AE40,Errors!$D:$D,Analysis!$AF$2) -> 0 | AG11: =COUNTIFS(Errors!$F:$F,Analysis!$AE40,Errors!$D:$D,Analysis!$AG$2) -> 0 | AH11: =COUNTIFS(Errors!$F:$F,Analysis!$AE40,Errors!$D:$D,Analysis!$AH$2) -> 0 | AI11: =COUNTIFS(Errors!$F:$F,Analysis!$AE40,Errors!$D:$D,Analysis!$AI$2) -> 0 | AJ11: =COUNTIFS(Errors!$F:$F,Analysis!$AE40,Errors!$D:$D,Analysis!$AJ$2) -> 0 | AK11: =COUNTIFS(Errors!$F:$F,Analysis!$AE40,Errors!$D:$D,Analysis!$AK$2) -> 0 | AL11: =COUNTIFS(Errors!$F:$F,Analysis!$AE40,Errors!$D:$D,Analysis!$AL$2) -> 0 | AM11: =COUNTIFS(Errors!$F:$F,Analysis!$AE40,Errors!$D:$D,Analysis!$AM$2) -> 0 | AN11: =COUNTIFS(Errors!$F:$F,Analysis!$AE40,Errors!$D:$D,Analysis!$AN$2) -> 0 | AO11: =COUNTIFS(Errors!$F:$F,Analysis!$AE40,Errors!$D:$D,Analysis!$AO$2) -> 0 | AP11: =COUNTIFS(Errors!$F:$F,Analysis!$AE40,Errors!$D:$D,Analysis!$AP$2) -> 0 | AQ11: =COUNTIFS(Errors!$F:$F,Analysis!$AE40,Errors!$D:$D,Analysis!$AQ$2) -> 0 | AR11: =COUNTIFS(Errors!$F:$F,Analysis!$AE40,Errors!$D:$D,Analysis!$AR$2) -> 0 | AS11: =COUNTIFS(Errors!$F:$F,Analysis!$AE40,Errors!$D:$D,Analysis!$AS$2) -> 0 | AT11: =COUNTIFS(Errors!$F:$F,Analysis!$AE40,Errors!$D:$D,Analysis!$AT$2) -> 0 | AU11: =COUNTIFS(Errors!$F:$F,Analysis!$AE40,Errors!$D:$D,Analysis!$AU$2) -> 0 | AV11: =COUNTIFS(Errors!$F:$F,Analysis!$AE40,Errors!$D:$D,Analysis!$AV$2) -> 0 | AW11: =COUNTIFS(Errors!$F:$F,Analysis!$AE40,Errors!$D:$D,Analysis!$AW$2) -> 0 | AX11: =COUNTIFS(Errors!$F:$F,Analysis!$AE40,Errors!$D:$D,Analysis!$AX$2) -> 0 | AY11: =COUNTIFS(Errors!$F:$F,Analysis!$AE40,Errors!$D:$D,Analysis!$AY$2) -> 0 | AZ11: =COUNTIFS(Errors!$F:$F,Analysis!$AE40,Errors!$D:$D,Analysis!$AZ$2) -> 0 | BA11: =COUNTIFS(Errors!$F:$F,Analysis!$AE40,Errors!$D:$D,Analysis!$BA$2) -> 0 | BB11: =COUNTIFS(Errors!$F:$F,Analysis!$AE40,Errors!$D:$D,Analysis!$BB$2) -> 0 | BC11: =COUNTIFS(Errors!$F:$F,Analysis!$AE40,Errors!$D:$D,Analysis!$BC$2) -> 0 | BD11: =COUNTIFS(Errors!$F:$F,Analysis!$AE40,Errors!$D:$D,Analysis!$BD$2) -> 0 | BE11: =COUNTIFS(Errors!$F:$F,Analysis!$AE40,Errors!$D:$D,Analysis!$BE$2) -> 0 | BF11: =COUNTIFS(Errors!$F:$F,Analysis!$AE40,Errors!$D:$D,Analysis!$BF$2) -> 0 | BG11: =COUNTIFS(Errors!$F:$F,Analysis!$AE40,Errors!$D:$D,Analysis!$BG$2) -> 0 | BH11: =COUNTIFS(Errors!$F:$F,Analysis!$AE40,Errors!$D:$D,Analysis!$BH$2) -> 0 | BI11: =COUNTIFS(Errors!$F:$F,Analysis!$AE40,Errors!$D:$D,Analysis!$BI$2) -> 0 | BJ11: =COUNTIFS(Errors!$F:$F,Analysis!$AE40,Errors!$D:$D,Analysis!$BJ$2) -> 0 | BL11: =SUM(AF11:BJ11) -> 0 | BN11: =AVERAGE(AF11:BJ11) -> 0 | BO11: Baccarat_E9 | BS11: Baccarat_E9 | BT11: =COUNTIFS(Errors!$D:$D,Analysis!BT$1,Errors!$F:$F,Analysis!$BS11,Errors!$O:$O,"YES") -> 0 | BU11: =COUNTIFS(Errors!$D:$D,Analysis!BU$1,Errors!$F:$F,Analysis!$BS11,Errors!$O:$O,"YES") -> 0 | BV11: =COUNTIFS(Errors!$D:$D,Analysis!BV$1,Errors!$F:$F,Analysis!$BS11,Errors!$O:$O,"YES") -> 0 | BW11: =COUNTIFS(Errors!$D:$D,Analysis!BW$1,Errors!$F:$F,Analysis!$BS11,Errors!$O:$O,"YES") -> 0 | BX11: =COUNTIFS(Errors!$D:$D,Analysis!BX$1,Errors!$F:$F,Analysis!$BS11,Errors!$O:$O,"YES") -> 0 | BY11: =COUNTIFS(Errors!$D:$D,Analysis!BY$1,Errors!$F:$F,Analysis!$BS11,Errors!$O:$O,"YES") -> 0 | BZ11: =COUNTIFS(Errors!$D:$D,Analysis!BZ$1,Errors!$F:$F,Analysis!$BS11,Errors!$O:$O,"YES") -> 0 | CA11: =COUNTIFS(Errors!$D:$D,Analysis!CA$1,Errors!$F:$F,Analysis!$BS11,Errors!$O:$O,"YES") -> 0 | ... CX11: =COUNTIFS(Errors!$D:$D,Analysis!CX$1,Errors!$F:$F,Analysis!$BS11,Errors!$O:$O,"YES") -> 0 | CZ11: =SUM(BT11:CX11) -> 0 | DB11: =AVERAGE(BT11:CX11) -> 0 | DC11: Baccarat_E9
A12: Total Technical Errors By Game Type | B12: =SUM($B$3:$B$9) -> 58 | C12: =SUM($C$3:$C$9) -> 44 | D12: =SUM($D$3:$D$9) -> 14 | E12: =SUM($E$3:$E$9) -> 0 | H12: =COUNTIF(Errors!$F$3:$F$3008,$G12) -> 0 | I12: =COUNTIFS(Errors!$F$3:$F$3008,$G12,Errors!$I$3:$I$3008,"TV*") -> 0 | J12: =COUNTIFS(Errors!$F$3:$F$3008,$G12,Errors!$I$3:$I$3008,"<>TV*") -> 0 | K12: =COUNTIFS(Errors!$F$3:$F$3008,$G12,Errors!$Q$3:$Q$3008,"yes") -> 0 | N12: =COUNTIFS(Errors!$O$3:$O$3008,"Yes",Errors!$F$3:$F$3008,$M12)+COUNTIFS(Errors!$P$3:$P$3008,"Yes",Errors!$F$3:$F$3008,$M12) -> 0 | O12: =COUNTIFS(Errors!$O$3:$O$3008,"Yes",Errors!$F$3:$F$3008,$M12,Errors!$I$3:$I$3008,"TV*")+COUNTIFS(Errors!$P$3:$P$3008,"Yes",Errors!$F$3:$F$3008,$M12,Errors!$I$3:$I$3008,"TV*") -> 0 | P12: =COUNTIFS(Errors!$O$3:$O$3008,"Yes",Errors!$F$3:$F$3008,$M12,Errors!$I$3:$I$3008,"<>TV*")+COUNTIFS(Errors!$P$3:$P$3008,"Yes",Errors!$F$3:$F$3008,$M12,Errors!$I$3:$I$3008,"<>TV*") -> 0 | Q12: =COUNTIFS(Errors!$F$3:$F$3008,$M12,Errors!$O$3:$O$3008,"yes") -> 0 | R12: =COUNTIFS(Errors!$F$3:$F$3008,$M12,Errors!$P$3:$P$3008,"yes") -> 0 | AF12: =COUNTIFS(Errors!$F:$F,Analysis!$AE41,Errors!$D:$D,Analysis!$AF$2) -> 0 | AG12: =COUNTIFS(Errors!$F:$F,Analysis!$AE41,Errors!$D:$D,Analysis!$AG$2) -> 0 | AH12: =COUNTIFS(Errors!$F:$F,Analysis!$AE41,Errors!$D:$D,Analysis!$AH$2) -> 0 | AI12: =COUNTIFS(Errors!$F:$F,Analysis!$AE41,Errors!$D:$D,Analysis!$AI$2) -> 0 | AJ12: =COUNTIFS(Errors!$F:$F,Analysis!$AE41,Errors!$D:$D,Analysis!$AJ$2) -> 0 | AK12: =COUNTIFS(Errors!$F:$F,Analysis!$AE41,Errors!$D:$D,Analysis!$AK$2) -> 0 | AL12: =COUNTIFS(Errors!$F:$F,Analysis!$AE41,Errors!$D:$D,Analysis!$AL$2) -> 0 | AM12: =COUNTIFS(Errors!$F:$F,Analysis!$AE41,Errors!$D:$D,Analysis!$AM$2) -> 0 | AN12: =COUNTIFS(Errors!$F:$F,Analysis!$AE41,Errors!$D:$D,Analysis!$AN$2) -> 0 | AO12: =COUNTIFS(Errors!$F:$F,Analysis!$AE41,Errors!$D:$D,Analysis!$AO$2) -> 0 | AP12: =COUNTIFS(Errors!$F:$F,Analysis!$AE41,Errors!$D:$D,Analysis!$AP$2) -> 0 | AQ12: =COUNTIFS(Errors!$F:$F,Analysis!$AE41,Errors!$D:$D,Analysis!$AQ$2) -> 0 | AR12: =COUNTIFS(Errors!$F:$F,Analysis!$AE41,Errors!$D:$D,Analysis!$AR$2) -> 0 | AS12: =COUNTIFS(Errors!$F:$F,Analysis!$AE41,Errors!$D:$D,Analysis!$AS$2) -> 0 | AT12: =COUNTIFS(Errors!$F:$F,Analysis!$AE41,Errors!$D:$D,Analysis!$AT$2) -> 0 | AU12: =COUNTIFS(Errors!$F:$F,Analysis!$AE41,Errors!$D:$D,Analysis!$AU$2) -> 0 | AV12: =COUNTIFS(Errors!$F:$F,Analysis!$AE41,Errors!$D:$D,Analysis!$AV$2) -> 0 | AW12: =COUNTIFS(Errors!$F:$F,Analysis!$AE41,Errors!$D:$D,Analysis!$AW$2) -> 0 | AX12: =COUNTIFS(Errors!$F:$F,Analysis!$AE41,Errors!$D:$D,Analysis!$AX$2) -> 0 | AY12: =COUNTIFS(Errors!$F:$F,Analysis!$AE41,Errors!$D:$D,Analysis!$AY$2) -> 0 | AZ12: =COUNTIFS(Errors!$F:$F,Analysis!$AE41,Errors!$D:$D,Analysis!$AZ$2) -> 0 | BA12: =COUNTIFS(Errors!$F:$F,Analysis!$AE41,Errors!$D:$D,Analysis!$BA$2) -> 0 | BB12: =COUNTIFS(Errors!$F:$F,Analysis!$AE41,Errors!$D:$D,Analysis!$BB$2) -> 0 | BC12: =COUNTIFS(Errors!$F:$F,Analysis!$AE41,Errors!$D:$D,Analysis!$BC$2) -> 0 | BD12: =COUNTIFS(Errors!$F:$F,Analysis!$AE41,Errors!$D:$D,Analysis!$BD$2) -> 0 | BE12: =COUNTIFS(Errors!$F:$F,Analysis!$AE41,Errors!$D:$D,Analysis!$BE$2) -> 0 | BF12: =COUNTIFS(Errors!$F:$F,Analysis!$AE41,Errors!$D:$D,Analysis!$BF$2) -> 0 | BG12: =COUNTIFS(Errors!$F:$F,Analysis!$AE41,Errors!$D:$D,Analysis!$BG$2) -> 0 | BH12: =COUNTIFS(Errors!$F:$F,Analysis!$AE41,Errors!$D:$D,Analysis!$BH$2) -> 0 | BI12: =COUNTIFS(Errors!$F:$F,Analysis!$AE41,Errors!$D:$D,Analysis!$BI$2) -> 0 | BJ12: =COUNTIFS(Errors!$F:$F,Analysis!$AE41,Errors!$D:$D,Analysis!$BJ$2) -> 0 | BL12: =SUM(AF12:BJ12) -> 0 | BN12: =AVERAGE(AF12:BJ12) -> 0 | BO12: Baccarat_E10 | BS12: Baccarat_E10 | BT12: =COUNTIFS(Errors!$D:$D,Analysis!BT$1,Errors!$F:$F,Analysis!$BS12,Errors!$O:$O,"YES") -> 0 | BU12: =COUNTIFS(Errors!$D:$D,Analysis!BU$1,Errors!$F:$F,Analysis!$BS12,Errors!$O:$O,"YES") -> 0 | BV12: =COUNTIFS(Errors!$D:$D,Analysis!BV$1,Errors!$F:$F,Analysis!$BS12,Errors!$O:$O,"YES") -> 0 | BW12: =COUNTIFS(Errors!$D:$D,Analysis!BW$1,Errors!$F:$F,Analysis!$BS12,Errors!$O:$O,"YES") -> 0 | BX12: =COUNTIFS(Errors!$D:$D,Analysis!BX$1,Errors!$F:$F,Analysis!$BS12,Errors!$O:$O,"YES") -> 0 | BY12: =COUNTIFS(Errors!$D:$D,Analysis!BY$1,Errors!$F:$F,Analysis!$BS12,Errors!$O:$O,"YES") -> 0 | BZ12: =COUNTIFS(Errors!$D:$D,Analysis!BZ$1,Errors!$F:$F,Analysis!$BS12,Errors!$O:$O,"YES") -> 0 | CA12: =COUNTIFS(Errors!$D:$D,Analysis!CA$1,Errors!$F:$F,Analysis!$BS12,Errors!$O:$O,"YES") -> 0 | ... CX12: =COUNTIFS(Errors!$D:$D,Analysis!CX$1,Errors!$F:$F,Analysis!$BS12,Errors!$O:$O,"YES") -> 0 | CZ12: =SUM(BT12:CX12) -> 0 | DB12: =AVERAGE(BT12:CX12) -> 0 | DC12: Baccarat_E10
H13: =COUNTIF(Errors!$F$3:$F$3008,$G13) -> 0 | I13: =COUNTIFS(Errors!$F$3:$F$3008,$G13,Errors!$I$3:$I$3008,"TV*") -> 0 | J13: =COUNTIFS(Errors!$F$3:$F$3008,$G13,Errors!$I$3:$I$3008,"<>TV*") -> 0 | K13: =COUNTIFS(Errors!$F$3:$F$3008,$G13,Errors!$Q$3:$Q$3008,"yes") -> 0 | N13: =COUNTIFS(Errors!$O$3:$O$3008,"Yes",Errors!$F$3:$F$3008,$M13)+COUNTIFS(Errors!$P$3:$P$3008,"Yes",Errors!$F$3:$F$3008,$M13) -> 0 | O13: =COUNTIFS(Errors!$O$3:$O$3008,"Yes",Errors!$F$3:$F$3008,$M13,Errors!$I$3:$I$3008,"TV*")+COUNTIFS(Errors!$P$3:$P$3008,"Yes",Errors!$F$3:$F$3008,$M13,Errors!$I$3:$I$3008,"TV*") -> 0 | P13: =COUNTIFS(Errors!$O$3:$O$3008,"Yes",Errors!$F$3:$F$3008,$M13,Errors!$I$3:$I$3008,"<>TV*")+COUNTIFS(Errors!$P$3:$P$3008,"Yes",Errors!$F$3:$F$3008,$M13,Errors!$I$3:$I$3008,"<>TV*") -> 0 | Q13: =COUNTIFS(Errors!$F$3:$F$3008,$M13,Errors!$O$3:$O$3008,"yes") -> 0 | R13: =COUNTIFS(Errors!$F$3:$F$3008,$M13,Errors!$P$3:$P$3008,"yes") -> 0 | AF13: =COUNTIFS(Errors!$F:$F,Analysis!$AE42,Errors!$D:$D,Analysis!$AF$2) -> 0 | AG13: =COUNTIFS(Errors!$F:$F,Analysis!$AE42,Errors!$D:$D,Analysis!$AG$2) -> 0 | AH13: =COUNTIFS(Errors!$F:$F,Analysis!$AE42,Errors!$D:$D,Analysis!$AH$2) -> 0 | AI13: =COUNTIFS(Errors!$F:$F,Analysis!$AE42,Errors!$D:$D,Analysis!$AI$2) -> 0 | AJ13: =COUNTIFS(Errors!$F:$F,Analysis!$AE42,Errors!$D:$D,Analysis!$AJ$2) -> 0 | AK13: =COUNTIFS(Errors!$F:$F,Analysis!$AE42,Errors!$D:$D,Analysis!$AK$2) -> 0 | AL13: =COUNTIFS(Errors!$F:$F,Analysis!$AE42,Errors!$D:$D,Analysis!$AL$2) -> 0 | AM13: =COUNTIFS(Errors!$F:$F,Analysis!$AE42,Errors!$D:$D,Analysis!$AM$2) -> 0 | AN13: =COUNTIFS(Errors!$F:$F,Analysis!$AE42,Errors!$D:$D,Analysis!$AN$2) -> 0 | AO13: =COUNTIFS(Errors!$F:$F,Analysis!$AE42,Errors!$D:$D,Analysis!$AO$2) -> 0 | AP13: =COUNTIFS(Errors!$F:$F,Analysis!$AE42,Errors!$D:$D,Analysis!$AP$2) -> 0 | AQ13: =COUNTIFS(Errors!$F:$F,Analysis!$AE42,Errors!$D:$D,Analysis!$AQ$2) -> 0 | AR13: =COUNTIFS(Errors!$F:$F,Analysis!$AE42,Errors!$D:$D,Analysis!$AR$2) -> 0 | AS13: =COUNTIFS(Errors!$F:$F,Analysis!$AE42,Errors!$D:$D,Analysis!$AS$2) -> 0 | AT13: =COUNTIFS(Errors!$F:$F,Analysis!$AE42,Errors!$D:$D,Analysis!$AT$2) -> 0 | AU13: =COUNTIFS(Errors!$F:$F,Analysis!$AE42,Errors!$D:$D,Analysis!$AU$2) -> 0 | AV13: =COUNTIFS(Errors!$F:$F,Analysis!$AE42,Errors!$D:$D,Analysis!$AV$2) -> 0 | AW13: =COUNTIFS(Errors!$F:$F,Analysis!$AE42,Errors!$D:$D,Analysis!$AW$2) -> 0 | AX13: =COUNTIFS(Errors!$F:$F,Analysis!$AE42,Errors!$D:$D,Analysis!$AX$2) -> 0 | AY13: =COUNTIFS(Errors!$F:$F,Analysis!$AE42,Errors!$D:$D,Analysis!$AY$2) -> 0 | AZ13: =COUNTIFS(Errors!$F:$F,Analysis!$AE42,Errors!$D:$D,Analysis!$AZ$2) -> 0 | BA13: =COUNTIFS(Errors!$F:$F,Analysis!$AE42,Errors!$D:$D,Analysis!$BA$2) -> 0 | BB13: =COUNTIFS(Errors!$F:$F,Analysis!$AE42,Errors!$D:$D,Analysis!$BB$2) -> 0 | BC13: =COUNTIFS(Errors!$F:$F,Analysis!$AE42,Errors!$D:$D,Analysis!$BC$2) -> 0 | BD13: =COUNTIFS(Errors!$F:$F,Analysis!$AE42,Errors!$D:$D,Analysis!$BD$2) -> 0 | BE13: =COUNTIFS(Errors!$F:$F,Analysis!$AE42,Errors!$D:$D,Analysis!$BE$2) -> 0 | BF13: =COUNTIFS(Errors!$F:$F,Analysis!$AE42,Errors!$D:$D,Analysis!$BF$2) -> 0 | BG13: =COUNTIFS(Errors!$F:$F,Analysis!$AE42,Errors!$D:$D,Analysis!$BG$2) -> 0 | BH13: =COUNTIFS(Errors!$F:$F,Analysis!$AE42,Errors!$D:$D,Analysis!$BH$2) -> 0 | BI13: =COUNTIFS(Errors!$F:$F,Analysis!$AE42,Errors!$D:$D,Analysis!$BI$2) -> 0 | BJ13: =COUNTIFS(Errors!$F:$F,Analysis!$AE42,Errors!$D:$D,Analysis!$BJ$2) -> 0 | BL13: =SUM(AF13:BJ13) -> 0 | BN13: =AVERAGE(AF13:BJ13) -> 0 | BO13: Baccarat_E11 | BS13: Baccarat_E11 | BT13: =COUNTIFS(Errors!$D:$D,Analysis!BT$1,Errors!$F:$F,Analysis!$BS13,Errors!$O:$O,"YES") -> 0 | BU13: =COUNTIFS(Errors!$D:$D,Analysis!BU$1,Errors!$F:$F,Analysis!$BS13,Errors!$O:$O,"YES") -> 0 | BV13: =COUNTIFS(Errors!$D:$D,Analysis!BV$1,Errors!$F:$F,Analysis!$BS13,Errors!$O:$O,"YES") -> 0 | BW13: =COUNTIFS(Errors!$D:$D,Analysis!BW$1,Errors!$F:$F,Analysis!$BS13,Errors!$O:$O,"YES") -> 0 | BX13: =COUNTIFS(Errors!$D:$D,Analysis!BX$1,Errors!$F:$F,Analysis!$BS13,Errors!$O:$O,"YES") -> 0 | BY13: =COUNTIFS(Errors!$D:$D,Analysis!BY$1,Errors!$F:$F,Analysis!$BS13,Errors!$O:$O,"YES") -> 0 | BZ13: =COUNTIFS(Errors!$D:$D,Analysis!BZ$1,Errors!$F:$F,Analysis!$BS13,Errors!$O:$O,"YES") -> 0 | CA13: =COUNTIFS(Errors!$D:$D,Analysis!CA$1,Errors!$F:$F,Analysis!$BS13,Errors!$O:$O,"YES") -> 0 | ... CX13: =COUNTIFS(Errors!$D:$D,Analysis!CX$1,Errors!$F:$F,Analysis!$BS13,Errors!$O:$O,"YES") -> 0 | CZ13: =SUM(BT13:CX13) -> 0 | DB13: =AVERAGE(BT13:CX13) -> 0 | DC13: Baccarat_E11
H14: =COUNTIF(Errors!$F$3:$F$3008,$G14) -> 0 | I14: =COUNTIFS(Errors!$F$3:$F$3008,$G14,Errors!$I$3:$I$3008,"TV*") -> 0 | J14: =COUNTIFS(Errors!$F$3:$F$3008,$G14,Errors!$I$3:$I$3008,"<>TV*") -> 0 | K14: =COUNTIFS(Errors!$F$3:$F$3008,$G14,Errors!$Q$3:$Q$3008,"yes") -> 0 | N14: =COUNTIFS(Errors!$O$3:$O$3008,"Yes",Errors!$F$3:$F$3008,$M14)+COUNTIFS(Errors!$P$3:$P$3008,"Yes",Errors!$F$3:$F$3008,$M14) -> 0 | O14: =COUNTIFS(Errors!$O$3:$O$3008,"Yes",Errors!$F$3:$F$3008,$M14,Errors!$I$3:$I$3008,"TV*")+COUNTIFS(Errors!$P$3:$P$3008,"Yes",Errors!$F$3:$F$3008,$M14,Errors!$I$3:$I$3008,"TV*") -> 0 | P14: =COUNTIFS(Errors!$O$3:$O$3008,"Yes",Errors!$F$3:$F$3008,$M14,Errors!$I$3:$I$3008,"<>TV*")+COUNTIFS(Errors!$P$3:$P$3008,"Yes",Errors!$F$3:$F$3008,$M14,Errors!$I$3:$I$3008,"<>TV*") -> 0 | Q14: =COUNTIFS(Errors!$F$3:$F$3008,$M14,Errors!$O$3:$O$3008,"yes") -> 0 | R14: =COUNTIFS(Errors!$F$3:$F$3008,$M14,Errors!$P$3:$P$3008,"yes") -> 0 | AF14: =COUNTIFS(Errors!$F:$F,Analysis!$AE43,Errors!$D:$D,Analysis!$AF$2) -> 0 | AG14: =COUNTIFS(Errors!$F:$F,Analysis!$AE43,Errors!$D:$D,Analysis!$AG$2) -> 0 | AH14: =COUNTIFS(Errors!$F:$F,Analysis!$AE43,Errors!$D:$D,Analysis!$AH$2) -> 0 | AI14: =COUNTIFS(Errors!$F:$F,Analysis!$AE43,Errors!$D:$D,Analysis!$AI$2) -> 0 | AJ14: =COUNTIFS(Errors!$F:$F,Analysis!$AE43,Errors!$D:$D,Analysis!$AJ$2) -> 0 | AK14: =COUNTIFS(Errors!$F:$F,Analysis!$AE43,Errors!$D:$D,Analysis!$AK$2) -> 0 | AL14: =COUNTIFS(Errors!$F:$F,Analysis!$AE43,Errors!$D:$D,Analysis!$AL$2) -> 0 | AM14: =COUNTIFS(Errors!$F:$F,Analysis!$AE43,Errors!$D:$D,Analysis!$AM$2) -> 0 | AN14: =COUNTIFS(Errors!$F:$F,Analysis!$AE43,Errors!$D:$D,Analysis!$AN$2) -> 0 | AO14: =COUNTIFS(Errors!$F:$F,Analysis!$AE43,Errors!$D:$D,Analysis!$AO$2) -> 0 | AP14: =COUNTIFS(Errors!$F:$F,Analysis!$AE43,Errors!$D:$D,Analysis!$AP$2) -> 0 | AQ14: =COUNTIFS(Errors!$F:$F,Analysis!$AE43,Errors!$D:$D,Analysis!$AQ$2) -> 0 | AR14: =COUNTIFS(Errors!$F:$F,Analysis!$AE43,Errors!$D:$D,Analysis!$AR$2) -> 0 | AS14: =COUNTIFS(Errors!$F:$F,Analysis!$AE43,Errors!$D:$D,Analysis!$AS$2) -> 0 | AT14: =COUNTIFS(Errors!$F:$F,Analysis!$AE43,Errors!$D:$D,Analysis!$AT$2) -> 0 | AU14: =COUNTIFS(Errors!$F:$F,Analysis!$AE43,Errors!$D:$D,Analysis!$AU$2) -> 0 | AV14: =COUNTIFS(Errors!$F:$F,Analysis!$AE43,Errors!$D:$D,Analysis!$AV$2) -> 0 | AW14: =COUNTIFS(Errors!$F:$F,Analysis!$AE43,Errors!$D:$D,Analysis!$AW$2) -> 0 | AX14: =COUNTIFS(Errors!$F:$F,Analysis!$AE43,Errors!$D:$D,Analysis!$AX$2) -> 0 | AY14: =COUNTIFS(Errors!$F:$F,Analysis!$AE43,Errors!$D:$D,Analysis!$AY$2) -> 0 | AZ14: =COUNTIFS(Errors!$F:$F,Analysis!$AE43,Errors!$D:$D,Analysis!$AZ$2) -> 0 | BA14: =COUNTIFS(Errors!$F:$F,Analysis!$AE43,Errors!$D:$D,Analysis!$BA$2) -> 0 | BB14: =COUNTIFS(Errors!$F:$F,Analysis!$AE43,Errors!$D:$D,Analysis!$BB$2) -> 0 | BC14: =COUNTIFS(Errors!$F:$F,Analysis!$AE43,Errors!$D:$D,Analysis!$BC$2) -> 0 | BD14: =COUNTIFS(Errors!$F:$F,Analysis!$AE43,Errors!$D:$D,Analysis!$BD$2) -> 0 | BE14: =COUNTIFS(Errors!$F:$F,Analysis!$AE43,Errors!$D:$D,Analysis!$BE$2) -> 0 | BF14: =COUNTIFS(Errors!$F:$F,Analysis!$AE43,Errors!$D:$D,Analysis!$BF$2) -> 0 | BG14: =COUNTIFS(Errors!$F:$F,Analysis!$AE43,Errors!$D:$D,Analysis!$BG$2) -> 0 | BH14: =COUNTIFS(Errors!$F:$F,Analysis!$AE43,Errors!$D:$D,Analysis!$BH$2) -> 0 | BI14: =COUNTIFS(Errors!$F:$F,Analysis!$AE43,Errors!$D:$D,Analysis!$BI$2) -> 0 | BJ14: =COUNTIFS(Errors!$F:$F,Analysis!$AE43,Errors!$D:$D,Analysis!$BJ$2) -> 0 | BL14: =SUM(AF14:BJ14) -> 0 | BN14: =AVERAGE(AF14:BJ14) -> 0 | BO14: Baccarat_E12 | BS14: Baccarat_E12 | BT14: =COUNTIFS(Errors!$D:$D,Analysis!BT$1,Errors!$F:$F,Analysis!$BS14,Errors!$O:$O,"YES") -> 0 | BU14: =COUNTIFS(Errors!$D:$D,Analysis!BU$1,Errors!$F:$F,Analysis!$BS14,Errors!$O:$O,"YES") -> 0 | BV14: =COUNTIFS(Errors!$D:$D,Analysis!BV$1,Errors!$F:$F,Analysis!$BS14,Errors!$O:$O,"YES") -> 0 | BW14: =COUNTIFS(Errors!$D:$D,Analysis!BW$1,Errors!$F:$F,Analysis!$BS14,Errors!$O:$O,"YES") -> 0 | BX14: =COUNTIFS(Errors!$D:$D,Analysis!BX$1,Errors!$F:$F,Analysis!$BS14,Errors!$O:$O,"YES") -> 0 | BY14: =COUNTIFS(Errors!$D:$D,Analysis!BY$1,Errors!$F:$F,Analysis!$BS14,Errors!$O:$O,"YES") -> 0 | BZ14: =COUNTIFS(Errors!$D:$D,Analysis!BZ$1,Errors!$F:$F,Analysis!$BS14,Errors!$O:$O,"YES") -> 0 | CA14: =COUNTIFS(Errors!$D:$D,Analysis!CA$1,Errors!$F:$F,Analysis!$BS14,Errors!$O:$O,"YES") -> 0 | ... CX14: =COUNTIFS(Errors!$D:$D,Analysis!CX$1,Errors!$F:$F,Analysis!$BS14,Errors!$O:$O,"YES") -> 0 | CZ14: =SUM(BT14:CX14) -> 0 | DB14: =AVERAGE(BT14:CX14) -> 0 | DC14: Baccarat_E12
